Workbook

Sheet Fats Raw Data
A1: {=_xldudf_BCTS(B1:I1,B2:I2,"Aggregation=Daily","AggSize=1","AggSpec=Continue",DATE(2026,5,8),,,,"Sort=Desc","Orientation=Vertical","Roll=1","Volume=Contract","Bars=1")} -> History | B1: LEG27 | K1: {=_xldudf_BCTS(L1:S1,L2:S2,"Aggregation=Daily","AggSize=1","AggSpec=Continue",DATE(2026,5,8),,,,"Sort=Desc","Orientation=Vertical","Roll=1","Volume=Contract","Bars=1")} -> History | L1: LEJ27 | U1: {=_xldudf_BCTS(V1:AC1,V2:AC2,"Aggregation=Daily","AggSize=1","AggSpec=Continue",DATE(2026,5,8),,,,"Sort=Desc","Orientation=Vertical","Roll=1","Volume=Contract","Bars=1")} -> History | V1: LEM26 | AE1: {=_xldudf_BCTS(AF1:AM1,AF2:AM2,"Aggregation=Daily","AggSize=1","AggSpec=Continue",DATE(2026,5,8),,,,"Sort=Desc","Orientation=Vertical","Roll=1","Volume=Contract","Bars=1")} -> History | AF1: LEQ26 | AO1: {=_xldudf_BCTS(AP1:AW1,AP2:AW2,"Aggregation=Daily","AggSize=1","AggSpec=Continue",DATE(2026,5,8),,,,"Sort=Desc","Orientation=Vertical","Roll=1","Volume=Contract","Bars=1")} -> History | AP1: LEV26 | AY1: {=_xldudf_BCTS(AZ1:BG1,AZ2:BG2,"Aggregation=Daily","AggSize=1","AggSpec=Continue",DATE(2026,5,8),,,,"Sort=Desc","Orientation=Vertical","Roll=1","Volume=Contract","Bars=1")} -> History | AZ1: LEZ26
A2: Date | B2: Close | C2: Open | D2: High | E2: Low | F2: Change | G2: Volume | H2: OpenInterest | I2: Symbol | K2: Date | L2: Close | M2: Open | N2: High | O2: Low | P2: Change | Q2: Volume | R2: OpenInterest | S2: Symbol | U2: Date | V2: Close | W2: Open | X2: High | Y2: Low | Z2: Change | AA2: Volume | AB2: OpenInterest | AC2: Symbol | AE2: Date | AF2: Close | AG2: Open | AH2: High | AI2: Low | AJ2: Change | AK2: Volume | AL2: OpenInterest | AM2: Symbol | AO2: Date | AP2: Close | AQ2: Open | AR2: High | AS2: Low | AT2: Change | AU2: Volume | AV2: OpenInterest | AW2: Symbol | AY2: Date | AZ2: Close | BA2: Open | BB2: High | BC2: Low | BD2: Change | BE2: Volume | BF2: OpenInterest | BG2: Symbol
A3: 46150 | B3: 237.45 | C3: 240.925 | D3: 241.625 | E3: 236.75 | F3: 0 | G3: 4095 | I3: LEG27 | K3: 46150 | L3: 236.825 | M3: 238.5 | N3: 241 | O3: 236.175 | P3: 0 | Q3: 1132 | S3: LEJ27 | U3: 46150 | V3: 248.9 | W3: 251.6 | X3: 253.725 | Y3: 248.7 | Z3: 0 | AA3: 32463 | AC3: LEM26 | AE3: 46150 | AF3: 244.1 | AG3: 247.275 | AH3: 249.3 | AI3: 243.95 | AJ3: 0 | AK3: 29718 | AM3: LEQ26 | AO3: 46150 | AP3: 238.3 | AQ3: 241.05 | AR3: 242.925 | AS3: 237.725 | AT3: 0 | AU3: 13679 | AW3: LEV26 | AY3: 46150 | AZ3: 237.525 | BA3: 239.975 | BB3: 242 | BC3: 236.8 | BD3: 0 | BE3: 9305 | BG3: LEZ26

Sheet Feeders Raw Data
A1: {=_xldudf_BCTS(B1:I1,B2:I2,"Aggregation=Daily","AggSize=1","AggSpec=Continue",DATE(2026,5,8),,,,"Sort=Desc","Orientation=Vertical","Roll=1","Volume=Contract","Bars=1")} -> History | B1: GFF27 | K1: {=_xldudf_BCTS(L1:S1,L2:S2,"Aggregation=Daily","AggSize=1","AggSpec=Continue",DATE(2026,5,8),,,,"Sort=Desc","Orientation=Vertical","Roll=1","Volume=Contract","Bars=1")} -> History | L1: GFH27 | U1: {=_xldudf_BCTS(V1:AC1,V2:AC2,"Aggregation=Daily","AggSize=1","AggSpec=Continue",DATE(2026,5,8),,,,"Sort=Desc","Orientation=Vertical","Roll=1","Volume=Contract","Bars=1")} -> History | V1: GFJ27 | AE1: {=_xldudf_BCTS(AF1:AM1,AF2:AM2,"Aggregation=Daily","AggSize=1","AggSpec=Continue",DATE(2026,5,8),,,,"Sort=Desc","Orientation=Vertical","Roll=1","Volume=Contract","Bars=1")} -> History | AF1: GFK26 | AO1: {=_xldudf_BCTS(AP1:AW1,AP2:AW2,"Aggregation=Daily","AggSize=1","AggSpec=Continue",DATE(2026,5,8),,,,"Sort=Desc","Orientation=Vertical","Roll=1","Volume=Contract","Bars=1")} -> History | AP1: GFQ26 | AY1: {=_xldudf_BCTS(AZ1:BG1,AZ2:BG2,"Aggregation=Daily","AggSize=1","AggSpec=Continue",DATE(2026,5,8),,,,"Sort=Desc","Orientation=Vertical","Roll=1","Volume=Contract","Bars=1")} -> History | AZ1: GFU26 | BI1: {=_xldudf_BCTS(BJ1:BQ1,BJ2:BQ2,"Aggregation=Daily","AggSize=1","AggSpec=Continue",DATE(2026,5,8),,,,"Sort=Desc","Orientation=Vertical","Roll=1","Volume=Contract","Bars=1")} -> History | BJ1: GFV26 | BS1: {=_xldudf_BCTS(BT1:CA1,BT2:CA2,"Aggregation=Daily","AggSize=1","AggSpec=Continue",DATE(2026,5,8),,,,"Sort=Desc","Orientation=Vertical","Roll=1","Volume=Contract","Bars=1")} -> History | BT1: GFX26
A2: Date | B2: Close | C2: Open | D2: High | E2: Low | F2: Change | G2: Volume | H2: OpenInterest | I2: Symbol | K2: Date | L2: Close | M2: Open | N2: High | O2: Low | P2: Change | Q2: Volume | R2: OpenInterest | S2: Symbol | U2: Date | V2: Close | W2: Open | X2: High | Y2: Low | Z2: Change | AA2: Volume | AB2: OpenInterest | AC2: Symbol | AE2: Date | AF2: Close | AG2: Open | AH2: High | AI2: Low | AJ2: Change | AK2: Volume | AL2: OpenInterest | AM2: Symbol | AO2: Date | AP2: Close | AQ2: Open | AR2: High | AS2: Low | AT2: Change | AU2: Volume | AV2: OpenInterest | AW2: Symbol | AY2: Date | AZ2: Close | BA2: Open | BB2: High | BC2: Low | BD2: Change | BE2: Volume | BF2: OpenInterest | BG2: Symbol | BI2: Date | BJ2: Close | BK2: Open | BL2: High | BM2: Low | BN2: Change | BO2: Volume | BP2: OpenInterest | BQ2: Symbol | BS2: Date | BT2: Close | BU2: Open | BV2: High | BW2: Low | BX2: Change | BY2: Volume | BZ2: OpenInterest | CA2: Symbol
A3: 46150 | B3: 350.65 | C3: 357.1 | D3: 357.7 | E3: 348.85 | F3: 0 | G3: 246 | I3: GFF27 | K3: 46150 | L3: 346.2 | M3: 349.35 | N3: 352.025 | O3: 344.475 | P3: 0 | Q3: 74 | S3: GFH27 | U3: 46150 | V3: 344.525 | W3: 343.4 | X3: 349.8 | Y3: 342.65 | Z3: 0 | AA3: 20 | AC3: GFJ27 | AE3: 46150 | AF3: 367.375 | AG3: 368.325 | AH3: 370.25 | AI3: 365.025 | AJ3: 0 | AK3: 3955 | AM3: GFK26 | AO3: 46150 | AP3: 364.225 | AQ3: 368.5 | AR3: 370.4 | AS3: 361.6 | AT3: 0 | AU3: 12055 | AW3: GFQ26 | AY3: 46150 | AZ3: 362.225 | BA3: 367.225 | BB3: 369 | BC3: 359.85 | BD3: 0 | BE3: 4208 | BG3: GFU26 | BI3: 46150 | BJ3: 359.8 | BK3: 365.525 | BL3: 366.475 | BM3: 357.6 | BN3: 0 | BO3: 1969 | BQ3: GFV26 | BS3: 46150 | BT3: 356.725 | BU3: 361.475 | BV3: 363.7 | BW3: 354.75 | BX3: 0 | BY3: 824 | CA3: GFX26

Sheet Fat Spreads
A1: LEJ - LEM (16 Years) | H1: LEM - LEQ (16 Years) | O1: LEQ - LEV (16 Years) | V1: LEV - LEZ (16 Years) | AC1: LEZ - LEG (16 Years) | AJ1: LEG - LEJ (16 Years) | AQ1: LEQ - LEZ (16 Years) | AX1: LEG - LEM (16 Years) | BE1: LEJ - LEQ (16 Years)
A2: Date | B2: Close | C2: Open | D2: High | E2: Low | F2: Spread Year | H2: Date | I2: Close | J2: Open | K2: High | L2: Low | M2: Spread Year | O2: Date | P2: Close | Q2: Open | R2: High | S2: Low | T2: Spread Year | V2: Date | W2: Close | X2: Open | Y2: High | Z2: Low | AA2: Spread Year | AC2: Date | AD2: Close | AE2: Open | AF2: High | AG2: Low | AH2: Spread Year | AJ2: Date | AK2: Close | AL2: Open | AM2: High | AN2: Low | AO2: Spread Year | AQ2: Date | AR2: Close | AS2: Open | AT2: High | AU2: Low | AV2: Spread Year | AX2: Date | AY2: Close | AZ2: Open | BA2: High | BB2: Low | BC2: Spread Year | BE2: Date | BF2: Close | BG2: Open | BH2: High | BI2: Low | BJ2: Spread Year
A3: ='Fats Raw Data'!K3 -> 46150 | B3: ='Fats Raw Data'!L3-'Fats Raw Data'!V3 -> -12.075 | C3: ='Fats Raw Data'!M3-'Fats Raw Data'!W3 -> -13.1 | D3: ='Fats Raw Data'!N3-'Fats Raw Data'!X3 -> -12.725 | E3: ='Fats Raw Data'!O3-'Fats Raw Data'!Y3 -> -12.525 | F3: ='Fats Raw Data'!S3&" - "&'Fats Raw Data'!AC3 -> LEJ27 - LEM26 | H3: ='Fats Raw Data'!U3 -> 46150 | I3: ='Fats Raw Data'!V3-'Fats Raw Data'!AF3 -> 4.8 | J3: ='Fats Raw Data'!W3-'Fats Raw Data'!AG3 -> 4.325 | K3: ='Fats Raw Data'!X3-'Fats Raw Data'!AH3 -> 4.425 | L3: ='Fats Raw Data'!Y3-'Fats Raw Data'!AI3 -> 4.75 | M3: ='Fats Raw Data'!AC3&" - "&'Fats Raw Data'!AM3 -> LEM26 - LEQ26 | O3: ='Fats Raw Data'!AE3 -> 46150 | P3: ='Fats Raw Data'!AF3-'Fats Raw Data'!AP3 -> 5.8 | Q3: ='Fats Raw Data'!AG3-'Fats Raw Data'!AQ3 -> 6.225 | R3: ='Fats Raw Data'!AH3-'Fats Raw Data'!AR3 -> 6.375 | S3: ='Fats Raw Data'!AI3-'Fats Raw Data'!AS3 -> 6.225 | T3: ='Fats Raw Data'!AM3&" - "&'Fats Raw Data'!AW3 -> LEQ26 - LEV26 | V3: ='Fats Raw Data'!AO3 -> 46150 | W3: ='Fats Raw Data'!AP3-'Fats Raw Data'!AZ3 -> 0.775 | X3: ='Fats Raw Data'!AQ3-'Fats Raw Data'!BA3 -> 1.075 | Y3: ='Fats Raw Data'!AR3-'Fats Raw Data'!BB3 -> 0.925 | Z3: ='Fats Raw Data'!AS3-'Fats Raw Data'!BC3 -> 0.925 | AA3: ='Fats Raw Data'!AW3&" - "&'Fats Raw Data'!BG3 -> LEV26 - LEZ26 | AC3: ='Fats Raw Data'!AY3 -> 46150 | AD3: ='Fats Raw Data'!AZ3-'Fats Raw Data'!B3 -> 0.075 | AE3: ='Fats Raw Data'!BA3-'Fats Raw Data'!C3 -> -0.95 | AF3: ='Fats Raw Data'!BB3-'Fats Raw Data'!D3 -> 0.375 | AG3: ='Fats Raw Data'!BC3-'Fats Raw Data'!E3 -> 0.05 | AH3: ='Fats Raw Data'!BG3&" - "&'Fats Raw Data'!I3 -> LEZ26 - LEG27 | AJ3: ='Fats Raw Data'!A3 -> 46150 | AK3: ='Fats Raw Data'!B3-'Fats Raw Data'!L3 -> 0.625 | AL3: ='Fats Raw Data'!C3-'Fats Raw Data'!M3 -> 2.425 | AM3: ='Fats Raw Data'!D3-'Fats Raw Data'!N3 -> 0.625 | AN3: ='Fats Raw Data'!E3-'Fats Raw Data'!O3 -> 0.575 | AO3: ='Fats Raw Data'!I3&" - "&'Fats Raw Data'!S3 -> LEG27 - LEJ27 | AQ3: ='Fats Raw Data'!AE3 -> 46150 | AR3: ='Fats Raw Data'!AF3-'Fats Raw Data'!AZ3 -> 6.575 | AS3: ='Fats Raw Data'!AG3-'Fats Raw Data'!BA3 -> 7.3 | AT3: ='Fats Raw Data'!AH3-'Fats Raw Data'!BB3 -> 7.3 | AU3: ='Fats Raw Data'!AI3-'Fats Raw Data'!BC3 -> 7.15 | AV3: ='Fats Raw Data'!AM3&" - "&'Fats Raw Data'!BG3 -> LEQ26 - LEZ26 | AX3: ='Fats Raw Data'!A3 -> 46150 | AY3: ='Fats Raw Data'!B3-'Fats Raw Data'!V3 -> -11.45 | AZ3: ='Fats Raw Data'!C3-'Fats Raw Data'!W3 -> -10.675 | BA3: ='Fats Raw Data'!D3-'Fats Raw Data'!X3 -> -12.1 | BB3: ='Fats Raw Data'!E3-'Fats Raw Data'!Y3 -> -11.95 | BC3: ='Fats Raw Data'!I3&" - "&'Fats Raw Data'!AC3 -> LEG27 - LEM26 | BE3: ='Fats Raw Data'!K3 -> 46150 | BF3: ='Fats Raw Data'!L3-'Fats Raw Data'!AF3 -> -7.275 | BG3: ='Fats Raw Data'!M3-'Fats Raw Data'!AG3 -> -8.775 | BH3: ='Fats Raw Data'!N3-'Fats Raw Data'!AH3 -> -8.3 | BI3: ='Fats Raw Data'!O3-'Fats Raw Data'!AI3 -> -7.775 | BJ3: ='Fats Raw Data'!S3&" - "&'Fats Raw Data'!AM3 -> LEJ27 - LEQ26
A4: ='Fats Raw Data'!K4 -> 0 | B4: ='Fats Raw Data'!L4-'Fats Raw Data'!V4 -> 0 | C4: ='Fats Raw Data'!M4-'Fats Raw Data'!W4 -> 0 | D4: ='Fats Raw Data'!N4-'Fats Raw Data'!X4 -> 0 | E4: ='Fats Raw Data'!O4-'Fats Raw Data'!Y4 -> 0 | F4: ='Fats Raw Data'!S4&" - "&'Fats Raw Data'!AC4 -> - | H4: ='Fats Raw Data'!U4 -> 0 | I4: ='Fats Raw Data'!V4-'Fats Raw Data'!AF4 -> 0 | J4: ='Fats Raw Data'!W4-'Fats Raw Data'!AG4 -> 0 | K4: ='Fats Raw Data'!X4-'Fats Raw Data'!AH4 -> 0 | L4: ='Fats Raw Data'!Y4-'Fats Raw Data'!AI4 -> 0 | M4: ='Fats Raw Data'!AC4&" - "&'Fats Raw Data'!AM4 -> - | O4: ='Fats Raw Data'!AE4 -> 0 | P4: ='Fats Raw Data'!AF4-'Fats Raw Data'!AP4 -> 0 | Q4: ='Fats Raw Data'!AG4-'Fats Raw Data'!AQ4 -> 0 | R4: ='Fats Raw Data'!AH4-'Fats Raw Data'!AR4 -> 0 | S4: ='Fats Raw Data'!AI4-'Fats Raw Data'!AS4 -> 0 | T4: ='Fats Raw Data'!AM4&" - "&'Fats Raw Data'!AW4 -> - | V4: ='Fats Raw Data'!AO4 -> 0 | W4: ='Fats Raw Data'!AP4-'Fats Raw Data'!AZ4 -> 0 | X4: ='Fats Raw Data'!AQ4-'Fats Raw Data'!BA4 -> 0 | Y4: ='Fats Raw Data'!AR4-'Fats Raw Data'!BB4 -> 0 | Z4: ='Fats Raw Data'!AS4-'Fats Raw Data'!BC4 -> 0 | AA4: ='Fats Raw Data'!AW4&" - "&'Fats Raw Data'!BG4 -> - | AC4: ='Fats Raw Data'!AY4 -> 0 | AD4: ='Fats Raw Data'!AZ4-'Fats Raw Data'!B4 -> 0 | AE4: ='Fats Raw Data'!BA4-'Fats Raw Data'!C4 -> 0 | AF4: ='Fats Raw Data'!BB4-'Fats Raw Data'!D4 -> 0 | AG4: ='Fats Raw Data'!BC4-'Fats Raw Data'!E4 -> 0 | AH4: ='Fats Raw Data'!BG4&" - "&'Fats Raw Data'!I4 -> - | AJ4: ='Fats Raw Data'!A4 -> 0 | AK4: ='Fats Raw Data'!B4-'Fats Raw Data'!L4 -> 0 | AL4: ='Fats Raw Data'!C4-'Fats Raw Data'!M4 -> 0 | AM4: ='Fats Raw Data'!D4-'Fats Raw Data'!N4 -> 0 | AN4: ='Fats Raw Data'!E4-'Fats Raw Data'!O4 -> 0 | AO4: ='Fats Raw Data'!I4&" - "&'Fats Raw Data'!S4 -> - | AQ4: ='Fats Raw Data'!AE4 -> 0 | AR4: ='Fats Raw Data'!AF4-'Fats Raw Data'!AZ4 -> 0 | AS4: ='Fats Raw Data'!AG4-'Fats Raw Data'!BA4 -> 0 | AT4: ='Fats Raw Data'!AH4-'Fats Raw Data'!BB4 -> 0 | AU4: ='Fats Raw Data'!AI4-'Fats Raw Data'!BC4 -> 0 | AV4: ='Fats Raw Data'!AM4&" - "&'Fats Raw Data'!BG4 -> - | AX4: ='Fats Raw Data'!A4 -> 0 | AY4: ='Fats Raw Data'!B4-'Fats Raw Data'!V4 -> 0 | AZ4: ='Fats Raw Data'!C4-'Fats Raw Data'!W4 -> 0 | BA4: ='Fats Raw Data'!D4-'Fats Raw Data'!X4 -> 0 | BB4: ='Fats Raw Data'!E4-'Fats Raw Data'!Y4 -> 0 | BC4: ='Fats Raw Data'!I4&" - "&'Fats Raw Data'!AC4 -> - | BE4: ='Fats Raw Data'!K4 -> 0 | BF4: ='Fats Raw Data'!L4-'Fats Raw Data'!AF4 -> 0 | BG4: ='Fats Raw Data'!M4-'Fats Raw Data'!AG4 -> 0 | BH4: ='Fats Raw Data'!N4-'Fats Raw Data'!AH4 -> 0 | BI4: ='Fats Raw Data'!O4-'Fats Raw Data'!AI4 -> 0 | BJ4: ='Fats Raw Data'!S4&" - "&'Fats Raw Data'!AM4 -> -
A5: ='Fats Raw Data'!K5 -> 0 | B5: ='Fats Raw Data'!L5-'Fats Raw Data'!V5 -> 0 | C5: ='Fats Raw Data'!M5-'Fats Raw Data'!W5 -> 0 | D5: ='Fats Raw Data'!N5-'Fats Raw Data'!X5 -> 0 | E5: ='Fats Raw Data'!O5-'Fats Raw Data'!Y5 -> 0 | F5: ='Fats Raw Data'!S5&" - "&'Fats Raw Data'!AC5 -> - | H5: ='Fats Raw Data'!U5 -> 0 | I5: ='Fats Raw Data'!V5-'Fats Raw Data'!AF5 -> 0 | J5: ='Fats Raw Data'!W5-'Fats Raw Data'!AG5 -> 0 | K5: ='Fats Raw Data'!X5-'Fats Raw Data'!AH5 -> 0 | L5: ='Fats Raw Data'!Y5-'Fats Raw Data'!AI5 -> 0 | M5: ='Fats Raw Data'!AC5&" - "&'Fats Raw Data'!AM5 -> - | O5: ='Fats Raw Data'!AE5 -> 0 | P5: ='Fats Raw Data'!AF5-'Fats Raw Data'!AP5 -> 0 | Q5: ='Fats Raw Data'!AG5-'Fats Raw Data'!AQ5 -> 0 | R5: ='Fats Raw Data'!AH5-'Fats Raw Data'!AR5 -> 0 | S5: ='Fats Raw Data'!AI5-'Fats Raw Data'!AS5 -> 0 | T5: ='Fats Raw Data'!AM5&" - "&'Fats Raw Data'!AW5 -> - | V5: ='Fats Raw Data'!AO5 -> 0 | W5: ='Fats Raw Data'!AP5-'Fats Raw Data'!AZ5 -> 0 | X5: ='Fats Raw Data'!AQ5-'Fats Raw Data'!BA5 -> 0 | Y5: ='Fats Raw Data'!AR5-'Fats Raw Data'!BB5 -> 0 | Z5: ='Fats Raw Data'!AS5-'Fats Raw Data'!BC5 -> 0 | AA5: ='Fats Raw Data'!AW5&" - "&'Fats Raw Data'!BG5 -> - | AC5: ='Fats Raw Data'!AY5 -> 0 | AD5: ='Fats Raw Data'!AZ5-'Fats Raw Data'!B5 -> 0 | AE5: ='Fats Raw Data'!BA5-'Fats Raw Data'!C5 -> 0 | AF5: ='Fats Raw Data'!BB5-'Fats Raw Data'!D5 -> 0 | AG5: ='Fats Raw Data'!BC5-'Fats Raw Data'!E5 -> 0 | AH5: ='Fats Raw Data'!BG5&" - "&'Fats Raw Data'!I5 -> - | AJ5: ='Fats Raw Data'!A5 -> 0 | AK5: ='Fats Raw Data'!B5-'Fats Raw Data'!L5 -> 0 | AL5: ='Fats Raw Data'!C5-'Fats Raw Data'!M5 -> 0 | AM5: ='Fats Raw Data'!D5-'Fats Raw Data'!N5 -> 0 | AN5: ='Fats Raw Data'!E5-'Fats Raw Data'!O5 -> 0 | AO5: ='Fats Raw Data'!I5&" - "&'Fats Raw Data'!S5 -> - | AQ5: ='Fats Raw Data'!AE5 -> 0 | AR5: ='Fats Raw Data'!AF5-'Fats Raw Data'!AZ5 -> 0 | AS5: ='Fats Raw Data'!AG5-'Fats Raw Data'!BA5 -> 0 | AT5: ='Fats Raw Data'!AH5-'Fats Raw Data'!BB5 -> 0 | AU5: ='Fats Raw Data'!AI5-'Fats Raw Data'!BC5 -> 0 | AV5: ='Fats Raw Data'!AM5&" - "&'Fats Raw Data'!BG5 -> - | AX5: ='Fats Raw Data'!A5 -> 0 | AY5: ='Fats Raw Data'!B5-'Fats Raw Data'!V5 -> 0 | AZ5: ='Fats Raw Data'!C5-'Fats Raw Data'!W5 -> 0 | BA5: ='Fats Raw Data'!D5-'Fats Raw Data'!X5 -> 0 | BB5: ='Fats Raw Data'!E5-'Fats Raw Data'!Y5 -> 0 | BC5: ='Fats Raw Data'!I5&" - "&'Fats Raw Data'!AC5 -> - | BE5: ='Fats Raw Data'!K5 -> 0 | BF5: ='Fats Raw Data'!L5-'Fats Raw Data'!AF5 -> 0 | BG5: ='Fats Raw Data'!M5-'Fats Raw Data'!AG5 -> 0 | BH5: ='Fats Raw Data'!N5-'Fats Raw Data'!AH5 -> 0 | BI5: ='Fats Raw Data'!O5-'Fats Raw Data'!AI5 -> 0 | BJ5: ='Fats Raw Data'!S5&" - "&'Fats Raw Data'!AM5 -> -
A6: ='Fats Raw Data'!K6 -> 0 | B6: ='Fats Raw Data'!L6-'Fats Raw Data'!V6 -> 0 | C6: ='Fats Raw Data'!M6-'Fats Raw Data'!W6 -> 0 | D6: ='Fats Raw Data'!N6-'Fats Raw Data'!X6 -> 0 | E6: ='Fats Raw Data'!O6-'Fats Raw Data'!Y6 -> 0 | F6: ='Fats Raw Data'!S6&" - "&'Fats Raw Data'!AC6 -> - | H6: ='Fats Raw Data'!U6 -> 0 | I6: ='Fats Raw Data'!V6-'Fats Raw Data'!AF6 -> 0 | J6: ='Fats Raw Data'!W6-'Fats Raw Data'!AG6 -> 0 | K6: ='Fats Raw Data'!X6-'Fats Raw Data'!AH6 -> 0 | L6: ='Fats Raw Data'!Y6-'Fats Raw Data'!AI6 -> 0 | M6: ='Fats Raw Data'!AC6&" - "&'Fats Raw Data'!AM6 -> - | O6: ='Fats Raw Data'!AE6 -> 0 | P6: ='Fats Raw Data'!AF6-'Fats Raw Data'!AP6 -> 0 | Q6: ='Fats Raw Data'!AG6-'Fats Raw Data'!AQ6 -> 0 | R6: ='Fats Raw Data'!AH6-'Fats Raw Data'!AR6 -> 0 | S6: ='Fats Raw Data'!AI6-'Fats Raw Data'!AS6 -> 0 | T6: ='Fats Raw Data'!AM6&" - "&'Fats Raw Data'!AW6 -> - | V6: ='Fats Raw Data'!AO6 -> 0 | W6: ='Fats Raw Data'!AP6-'Fats Raw Data'!AZ6 -> 0 | X6: ='Fats Raw Data'!AQ6-'Fats Raw Data'!BA6 -> 0 | Y6: ='Fats Raw Data'!AR6-'Fats Raw Data'!BB6 -> 0 | Z6: ='Fats Raw Data'!AS6-'Fats Raw Data'!BC6 -> 0 | AA6: ='Fats Raw Data'!AW6&" - "&'Fats Raw Data'!BG6 -> - | AC6: ='Fats Raw Data'!AY6 -> 0 | AD6: ='Fats Raw Data'!AZ6-'Fats Raw Data'!B6 -> 0 | AE6: ='Fats Raw Data'!BA6-'Fats Raw Data'!C6 -> 0 | AF6: ='Fats Raw Data'!BB6-'Fats Raw Data'!D6 -> 0 | AG6: ='Fats Raw Data'!BC6-'Fats Raw Data'!E6 -> 0 | AH6: ='Fats Raw Data'!BG6&" - "&'Fats Raw Data'!I6 -> - | AJ6: ='Fats Raw Data'!A6 -> 0 | AK6: ='Fats Raw Data'!B6-'Fats Raw Data'!L6 -> 0 | AL6: ='Fats Raw Data'!C6-'Fats Raw Data'!M6 -> 0 | AM6: ='Fats Raw Data'!D6-'Fats Raw Data'!N6 -> 0 | AN6: ='Fats Raw Data'!E6-'Fats Raw Data'!O6 -> 0 | AO6: ='Fats Raw Data'!I6&" - "&'Fats Raw Data'!S6 -> - | AQ6: ='Fats Raw Data'!AE6 -> 0 | AR6: ='Fats Raw Data'!AF6-'Fats Raw Data'!AZ6 -> 0 | AS6: ='Fats Raw Data'!AG6-'Fats Raw Data'!BA6 -> 0 | AT6: ='Fats Raw Data'!AH6-'Fats Raw Data'!BB6 -> 0 | AU6: ='Fats Raw Data'!AI6-'Fats Raw Data'!BC6 -> 0 | AV6: ='Fats Raw Data'!AM6&" - "&'Fats Raw Data'!BG6 -> - | AX6: ='Fats Raw Data'!A6 -> 0 | AY6: ='Fats Raw Data'!B6-'Fats Raw Data'!V6 -> 0 | AZ6: ='Fats Raw Data'!C6-'Fats Raw Data'!W6 -> 0 | BA6: ='Fats Raw Data'!D6-'Fats Raw Data'!X6 -> 0 | BB6: ='Fats Raw Data'!E6-'Fats Raw Data'!Y6 -> 0 | BC6: ='Fats Raw Data'!I6&" - "&'Fats Raw Data'!AC6 -> - | BE6: ='Fats Raw Data'!K6 -> 0 | BF6: ='Fats Raw Data'!L6-'Fats Raw Data'!AF6 -> 0 | BG6: ='Fats Raw Data'!M6-'Fats Raw Data'!AG6 -> 0 | BH6: ='Fats Raw Data'!N6-'Fats Raw Data'!AH6 -> 0 | BI6: ='Fats Raw Data'!O6-'Fats Raw Data'!AI6 -> 0 | BJ6: ='Fats Raw Data'!S6&" - "&'Fats Raw Data'!AM6 -> -
A7: ='Fats Raw Data'!K7 -> 0 | B7: ='Fats Raw Data'!L7-'Fats Raw Data'!V7 -> 0 | C7: ='Fats Raw Data'!M7-'Fats Raw Data'!W7 -> 0 | D7: ='Fats Raw Data'!N7-'Fats Raw Data'!X7 -> 0 | E7: ='Fats Raw Data'!O7-'Fats Raw Data'!Y7 -> 0 | F7: ='Fats Raw Data'!S7&" - "&'Fats Raw Data'!AC7 -> - | H7: ='Fats Raw Data'!U7 -> 0 | I7: ='Fats Raw Data'!V7-'Fats Raw Data'!AF7 -> 0 | J7: ='Fats Raw Data'!W7-'Fats Raw Data'!AG7 -> 0 | K7: ='Fats Raw Data'!X7-'Fats Raw Data'!AH7 -> 0 | L7: ='Fats Raw Data'!Y7-'Fats Raw Data'!AI7 -> 0 | M7: ='Fats Raw Data'!AC7&" - "&'Fats Raw Data'!AM7 -> - | O7: ='Fats Raw Data'!AE7 -> 0 | P7: ='Fats Raw Data'!AF7-'Fats Raw Data'!AP7 -> 0 | Q7: ='Fats Raw Data'!AG7-'Fats Raw Data'!AQ7 -> 0 | R7: ='Fats Raw Data'!AH7-'Fats Raw Data'!AR7 -> 0 | S7: ='Fats Raw Data'!AI7-'Fats Raw Data'!AS7 -> 0 | T7: ='Fats Raw Data'!AM7&" - "&'Fats Raw Data'!AW7 -> - | V7: ='Fats Raw Data'!AO7 -> 0 | W7: ='Fats Raw Data'!AP7-'Fats Raw Data'!AZ7 -> 0 | X7: ='Fats Raw Data'!AQ7-'Fats Raw Data'!BA7 -> 0 | Y7: ='Fats Raw Data'!AR7-'Fats Raw Data'!BB7 -> 0 | Z7: ='Fats Raw Data'!AS7-'Fats Raw Data'!BC7 -> 0 | AA7: ='Fats Raw Data'!AW7&" - "&'Fats Raw Data'!BG7 -> - | AC7: ='Fats Raw Data'!AY7 -> 0 | AD7: ='Fats Raw Data'!AZ7-'Fats Raw Data'!B7 -> 0 | AE7: ='Fats Raw Data'!BA7-'Fats Raw Data'!C7 -> 0 | AF7: ='Fats Raw Data'!BB7-'Fats Raw Data'!D7 -> 0 | AG7: ='Fats Raw Data'!BC7-'Fats Raw Data'!E7 -> 0 | AH7: ='Fats Raw Data'!BG7&" - "&'Fats Raw Data'!I7 -> - | AJ7: ='Fats Raw Data'!A7 -> 0 | AK7: ='Fats Raw Data'!B7-'Fats Raw Data'!L7 -> 0 | AL7: ='Fats Raw Data'!C7-'Fats Raw Data'!M7 -> 0 | AM7: ='Fats Raw Data'!D7-'Fats Raw Data'!N7 -> 0 | AN7: ='Fats Raw Data'!E7-'Fats Raw Data'!O7 -> 0 | AO7: ='Fats Raw Data'!I7&" - "&'Fats Raw Data'!S7 -> - | AQ7: ='Fats Raw Data'!AE7 -> 0 | AR7: ='Fats Raw Data'!AF7-'Fats Raw Data'!AZ7 -> 0 | AS7: ='Fats Raw Data'!AG7-'Fats Raw Data'!BA7 -> 0 | AT7: ='Fats Raw Data'!AH7-'Fats Raw Data'!BB7 -> 0 | AU7: ='Fats Raw Data'!AI7-'Fats Raw Data'!BC7 -> 0 | AV7: ='Fats Raw Data'!AM7&" - "&'Fats Raw Data'!BG7 -> - | AX7: ='Fats Raw Data'!A7 -> 0 | AY7: ='Fats Raw Data'!B7-'Fats Raw Data'!V7 -> 0 | AZ7: ='Fats Raw Data'!C7-'Fats Raw Data'!W7 -> 0 | BA7: ='Fats Raw Data'!D7-'Fats Raw Data'!X7 -> 0 | BB7: ='Fats Raw Data'!E7-'Fats Raw Data'!Y7 -> 0 | BC7: ='Fats Raw Data'!I7&" - "&'Fats Raw Data'!AC7 -> - | BE7: ='Fats Raw Data'!K7 -> 0 | BF7: ='Fats Raw Data'!L7-'Fats Raw Data'!AF7 -> 0 | BG7: ='Fats Raw Data'!M7-'Fats Raw Data'!AG7 -> 0 | BH7: ='Fats Raw Data'!N7-'Fats Raw Data'!AH7 -> 0 | BI7: ='Fats Raw Data'!O7-'Fats Raw Data'!AI7 -> 0 | BJ7: ='Fats Raw Data'!S7&" - "&'Fats Raw Data'!AM7 -> -
A8: ='Fats Raw Data'!K8 -> 0 | B8: ='Fats Raw Data'!L8-'Fats Raw Data'!V8 -> 0 | C8: ='Fats Raw Data'!M8-'Fats Raw Data'!W8 -> 0 | D8: ='Fats Raw Data'!N8-'Fats Raw Data'!X8 -> 0 | E8: ='Fats Raw Data'!O8-'Fats Raw Data'!Y8 -> 0 | F8: ='Fats Raw Data'!S8&" - "&'Fats Raw Data'!AC8 -> - | H8: ='Fats Raw Data'!U8 -> 0 | I8: ='Fats Raw Data'!V8-'Fats Raw Data'!AF8 -> 0 | J8: ='Fats Raw Data'!W8-'Fats Raw Data'!AG8 -> 0 | K8: ='Fats Raw Data'!X8-'Fats Raw Data'!AH8 -> 0 | L8: ='Fats Raw Data'!Y8-'Fats Raw Data'!AI8 -> 0 | M8: ='Fats Raw Data'!AC8&" - "&'Fats Raw Data'!AM8 -> - | O8: ='Fats Raw Data'!AE8 -> 0 | P8: ='Fats Raw Data'!AF8-'Fats Raw Data'!AP8 -> 0 | Q8: ='Fats Raw Data'!AG8-'Fats Raw Data'!AQ8 -> 0 | R8: ='Fats Raw Data'!AH8-'Fats Raw Data'!AR8 -> 0 | S8: ='Fats Raw Data'!AI8-'Fats Raw Data'!AS8 -> 0 | T8: ='Fats Raw Data'!AM8&" - "&'Fats Raw Data'!AW8 -> - | V8: ='Fats Raw Data'!AO8 -> 0 | W8: ='Fats Raw Data'!AP8-'Fats Raw Data'!AZ8 -> 0 | X8: ='Fats Raw Data'!AQ8-'Fats Raw Data'!BA8 -> 0 | Y8: ='Fats Raw Data'!AR8-'Fats Raw Data'!BB8 -> 0 | Z8: ='Fats Raw Data'!AS8-'Fats Raw Data'!BC8 -> 0 | AA8: ='Fats Raw Data'!AW8&" - "&'Fats Raw Data'!BG8 -> - | AC8: ='Fats Raw Data'!AY8 -> 0 | AD8: ='Fats Raw Data'!AZ8-'Fats Raw Data'!B8 -> 0 | AE8: ='Fats Raw Data'!BA8-'Fats Raw Data'!C8 -> 0 | AF8: ='Fats Raw Data'!BB8-'Fats Raw Data'!D8 -> 0 | AG8: ='Fats Raw Data'!BC8-'Fats Raw Data'!E8 -> 0 | AH8: ='Fats Raw Data'!BG8&" - "&'Fats Raw Data'!I8 -> - | AJ8: ='Fats Raw Data'!A8 -> 0 | AK8: ='Fats Raw Data'!B8-'Fats Raw Data'!L8 -> 0 | AL8: ='Fats Raw Data'!C8-'Fats Raw Data'!M8 -> 0 | AM8: ='Fats Raw Data'!D8-'Fats Raw Data'!N8 -> 0 | AN8: ='Fats Raw Data'!E8-'Fats Raw Data'!O8 -> 0 | AO8: ='Fats Raw Data'!I8&" - "&'Fats Raw Data'!S8 -> - | AQ8: ='Fats Raw Data'!AE8 -> 0 | AR8: ='Fats Raw Data'!AF8-'Fats Raw Data'!AZ8 -> 0 | AS8: ='Fats Raw Data'!AG8-'Fats Raw Data'!BA8 -> 0 | AT8: ='Fats Raw Data'!AH8-'Fats Raw Data'!BB8 -> 0 | AU8: ='Fats Raw Data'!AI8-'Fats Raw Data'!BC8 -> 0 | AV8: ='Fats Raw Data'!AM8&" - "&'Fats Raw Data'!BG8 -> - | AX8: ='Fats Raw Data'!A8 -> 0 | AY8: ='Fats Raw Data'!B8-'Fats Raw Data'!V8 -> 0 | AZ8: ='Fats Raw Data'!C8-'Fats Raw Data'!W8 -> 0 | BA8: ='Fats Raw Data'!D8-'Fats Raw Data'!X8 -> 0 | BB8: ='Fats Raw Data'!E8-'Fats Raw Data'!Y8 -> 0 | BC8: ='Fats Raw Data'!I8&" - "&'Fats Raw Data'!AC8 -> - | BE8: ='Fats Raw Data'!K8 -> 0 | BF8: ='Fats Raw Data'!L8-'Fats Raw Data'!AF8 -> 0 | BG8: ='Fats Raw Data'!M8-'Fats Raw Data'!AG8 -> 0 | BH8: ='Fats Raw Data'!N8-'Fats Raw Data'!AH8 -> 0 | BI8: ='Fats Raw Data'!O8-'Fats Raw Data'!AI8 -> 0 | BJ8: ='Fats Raw Data'!S8&" - "&'Fats Raw Data'!AM8 -> -
A9: ='Fats Raw Data'!K9 -> 0 | B9: ='Fats Raw Data'!L9-'Fats Raw Data'!V9 -> 0 | C9: ='Fats Raw Data'!M9-'Fats Raw Data'!W9 -> 0 | D9: ='Fats Raw Data'!N9-'Fats Raw Data'!X9 -> 0 | E9: ='Fats Raw Data'!O9-'Fats Raw Data'!Y9 -> 0 | F9: ='Fats Raw Data'!S9&" - "&'Fats Raw Data'!AC9 -> - | H9: ='Fats Raw Data'!U9 -> 0 | I9: ='Fats Raw Data'!V9-'Fats Raw Data'!AF9 -> 0 | J9: ='Fats Raw Data'!W9-'Fats Raw Data'!AG9 -> 0 | K9: ='Fats Raw Data'!X9-'Fats Raw Data'!AH9 -> 0 | L9: ='Fats Raw Data'!Y9-'Fats Raw Data'!AI9 -> 0 | M9: ='Fats Raw Data'!AC9&" - "&'Fats Raw Data'!AM9 -> - | O9: ='Fats Raw Data'!AE9 -> 0 | P9: ='Fats Raw Data'!AF9-'Fats Raw Data'!AP9 -> 0 | Q9: ='Fats Raw Data'!AG9-'Fats Raw Data'!AQ9 -> 0 | R9: ='Fats Raw Data'!AH9-'Fats Raw Data'!AR9 -> 0 | S9: ='Fats Raw Data'!AI9-'Fats Raw Data'!AS9 -> 0 | T9: ='Fats Raw Data'!AM9&" - "&'Fats Raw Data'!AW9 -> - | V9: ='Fats Raw Data'!AO9 -> 0 | W9: ='Fats Raw Data'!AP9-'Fats Raw Data'!AZ9 -> 0 | X9: ='Fats Raw Data'!AQ9-'Fats Raw Data'!BA9 -> 0 | Y9: ='Fats Raw Data'!AR9-'Fats Raw Data'!BB9 -> 0 | Z9: ='Fats Raw Data'!AS9-'Fats Raw Data'!BC9 -> 0 | AA9: ='Fats Raw Data'!AW9&" - "&'Fats Raw Data'!BG9 -> - | AC9: ='Fats Raw Data'!AY9 -> 0 | AD9: ='Fats Raw Data'!AZ9-'Fats Raw Data'!B9 -> 0 | AE9: ='Fats Raw Data'!BA9-'Fats Raw Data'!C9 -> 0 | AF9: ='Fats Raw Data'!BB9-'Fats Raw Data'!D9 -> 0 | AG9: ='Fats Raw Data'!BC9-'Fats Raw Data'!E9 -> 0 | AH9: ='Fats Raw Data'!BG9&" - "&'Fats Raw Data'!I9 -> - | AJ9: ='Fats Raw Data'!A9 -> 0 | AK9: ='Fats Raw Data'!B9-'Fats Raw Data'!L9 -> 0 | AL9: ='Fats Raw Data'!C9-'Fats Raw Data'!M9 -> 0 | AM9: ='Fats Raw Data'!D9-'Fats Raw Data'!N9 -> 0 | AN9: ='Fats Raw Data'!E9-'Fats Raw Data'!O9 -> 0 | AO9: ='Fats Raw Data'!I9&" - "&'Fats Raw Data'!S9 -> - | AQ9: ='Fats Raw Data'!AE9 -> 0 | AR9: ='Fats Raw Data'!AF9-'Fats Raw Data'!AZ9 -> 0 | AS9: ='Fats Raw Data'!AG9-'Fats Raw Data'!BA9 -> 0 | AT9: ='Fats Raw Data'!AH9-'Fats Raw Data'!BB9 -> 0 | AU9: ='Fats Raw Data'!AI9-'Fats Raw Data'!BC9 -> 0 | AV9: ='Fats Raw Data'!AM9&" - "&'Fats Raw Data'!BG9 -> - | AX9: ='Fats Raw Data'!A9 -> 0 | AY9: ='Fats Raw Data'!B9-'Fats Raw Data'!V9 -> 0 | AZ9: ='Fats Raw Data'!C9-'Fats Raw Data'!W9 -> 0 | BA9: ='Fats Raw Data'!D9-'Fats Raw Data'!X9 -> 0 | BB9: ='Fats Raw Data'!E9-'Fats Raw Data'!Y9 -> 0 | BC9: ='Fats Raw Data'!I9&" - "&'Fats Raw Data'!AC9 -> - | BE9: ='Fats Raw Data'!K9 -> 0 | BF9: ='Fats Raw Data'!L9-'Fats Raw Data'!AF9 -> 0 | BG9: ='Fats Raw Data'!M9-'Fats Raw Data'!AG9 -> 0 | BH9: ='Fats Raw Data'!N9-'Fats Raw Data'!AH9 -> 0 | BI9: ='Fats Raw Data'!O9-'Fats Raw Data'!AI9 -> 0 | BJ9: ='Fats Raw Data'!S9&" - "&'Fats Raw Data'!AM9 -> -
A10: ='Fats Raw Data'!K10 -> 0 | B10: ='Fats Raw Data'!L10-'Fats Raw Data'!V10 -> 0 | C10: ='Fats Raw Data'!M10-'Fats Raw Data'!W10 -> 0 | D10: ='Fats Raw Data'!N10-'Fats Raw Data'!X10 -> 0 | E10: ='Fats Raw Data'!O10-'Fats Raw Data'!Y10 -> 0 | F10: ='Fats Raw Data'!S10&" - "&'Fats Raw Data'!AC10 -> - | H10: ='Fats Raw Data'!U10 -> 0 | I10: ='Fats Raw Data'!V10-'Fats Raw Data'!AF10 -> 0 | J10: ='Fats Raw Data'!W10-'Fats Raw Data'!AG10 -> 0 | K10: ='Fats Raw Data'!X10-'Fats Raw Data'!AH10 -> 0 | L10: ='Fats Raw Data'!Y10-'Fats Raw Data'!AI10 -> 0 | M10: ='Fats Raw Data'!AC10&" - "&'Fats Raw Data'!AM10 -> - | O10: ='Fats Raw Data'!AE10 -> 0 | P10: ='Fats Raw Data'!AF10-'Fats Raw Data'!AP10 -> 0 | Q10: ='Fats Raw Data'!AG10-'Fats Raw Data'!AQ10 -> 0 | R10: ='Fats Raw Data'!AH10-'Fats Raw Data'!AR10 -> 0 | S10: ='Fats Raw Data'!AI10-'Fats Raw Data'!AS10 -> 0 | T10: ='Fats Raw Data'!AM10&" - "&'Fats Raw Data'!AW10 -> - | V10: ='Fats Raw Data'!AO10 -> 0 | W10: ='Fats Raw Data'!AP10-'Fats Raw Data'!AZ10 -> 0 | X10: ='Fats Raw Data'!AQ10-'Fats Raw Data'!BA10 -> 0 | Y10: ='Fats Raw Data'!AR10-'Fats Raw Data'!BB10 -> 0 | Z10: ='Fats Raw Data'!AS10-'Fats Raw Data'!BC10 -> 0 | AA10: ='Fats Raw Data'!AW10&" - "&'Fats Raw Data'!BG10 -> - | AC10: ='Fats Raw Data'!AY10 -> 0 | AD10: ='Fats Raw Data'!AZ10-'Fats Raw Data'!B10 -> 0 | AE10: ='Fats Raw Data'!BA10-'Fats Raw Data'!C10 -> 0 | AF10: ='Fats Raw Data'!BB10-'Fats Raw Data'!D10 -> 0 | AG10: ='Fats Raw Data'!BC10-'Fats Raw Data'!E10 -> 0 | AH10: ='Fats Raw Data'!BG10&" - "&'Fats Raw Data'!I10 -> - | AJ10: ='Fats Raw Data'!A10 -> 0 | AK10: ='Fats Raw Data'!B10-'Fats Raw Data'!L10 -> 0 | AL10: ='Fats Raw Data'!C10-'Fats Raw Data'!M10 -> 0 | AM10: ='Fats Raw Data'!D10-'Fats Raw Data'!N10 -> 0 | AN10: ='Fats Raw Data'!E10-'Fats Raw Data'!O10 -> 0 | AO10: ='Fats Raw Data'!I10&" - "&'Fats Raw Data'!S10 -> - | AQ10: ='Fats Raw Data'!AE10 -> 0 | AR10: ='Fats Raw Data'!AF10-'Fats Raw Data'!AZ10 -> 0 | AS10: ='Fats Raw Data'!AG10-'Fats Raw Data'!BA10 -> 0 | AT10: ='Fats Raw Data'!AH10-'Fats Raw Data'!BB10 -> 0 | AU10: ='Fats Raw Data'!AI10-'Fats Raw Data'!BC10 -> 0 | AV10: ='Fats Raw Data'!AM10&" - "&'Fats Raw Data'!BG10 -> - | AX10: ='Fats Raw Data'!A10 -> 0 | AY10: ='Fats Raw Data'!B10-'Fats Raw Data'!V10 -> 0 | AZ10: ='Fats Raw Data'!C10-'Fats Raw Data'!W10 -> 0 | BA10: ='Fats Raw Data'!D10-'Fats Raw Data'!X10 -> 0 | BB10: ='Fats Raw Data'!E10-'Fats Raw Data'!Y10 -> 0 | BC10: ='Fats Raw Data'!I10&" - "&'Fats Raw Data'!AC10 -> - | BE10: ='Fats Raw Data'!K10 -> 0 | BF10: ='Fats Raw Data'!L10-'Fats Raw Data'!AF10 -> 0 | BG10: ='Fats Raw Data'!M10-'Fats Raw Data'!AG10 -> 0 | BH10: ='Fats Raw Data'!N10-'Fats Raw Data'!AH10 -> 0 | BI10: ='Fats Raw Data'!O10-'Fats Raw Data'!AI10 -> 0 | BJ10: ='Fats Raw Data'!S10&" - "&'Fats Raw Data'!AM10 -> -
A11: ='Fats Raw Data'!K11 -> 0 | B11: ='Fats Raw Data'!L11-'Fats Raw Data'!V11 -> 0 | C11: ='Fats Raw Data'!M11-'Fats Raw Data'!W11 -> 0 | D11: ='Fats Raw Data'!N11-'Fats Raw Data'!X11 -> 0 | E11: ='Fats Raw Data'!O11-'Fats Raw Data'!Y11 -> 0 | F11: ='Fats Raw Data'!S11&" - "&'Fats Raw Data'!AC11 -> - | H11: ='Fats Raw Data'!U11 -> 0 | I11: ='Fats Raw Data'!V11-'Fats Raw Data'!AF11 -> 0 | J11: ='Fats Raw Data'!W11-'Fats Raw Data'!AG11 -> 0 | K11: ='Fats Raw Data'!X11-'Fats Raw Data'!AH11 -> 0 | L11: ='Fats Raw Data'!Y11-'Fats Raw Data'!AI11 -> 0 | M11: ='Fats Raw Data'!AC11&" - "&'Fats Raw Data'!AM11 -> - | O11: ='Fats Raw Data'!AE11 -> 0 | P11: ='Fats Raw Data'!AF11-'Fats Raw Data'!AP11 -> 0 | Q11: ='Fats Raw Data'!AG11-'Fats Raw Data'!AQ11 -> 0 | R11: ='Fats Raw Data'!AH11-'Fats Raw Data'!AR11 -> 0 | S11: ='Fats Raw Data'!AI11-'Fats Raw Data'!AS11 -> 0 | T11: ='Fats Raw Data'!AM11&" - "&'Fats Raw Data'!AW11 -> - | V11: ='Fats Raw Data'!AO11 -> 0 | W11: ='Fats Raw Data'!AP11-'Fats Raw Data'!AZ11 -> 0 | X11: ='Fats Raw Data'!AQ11-'Fats Raw Data'!BA11 -> 0 | Y11: ='Fats Raw Data'!AR11-'Fats Raw Data'!BB11 -> 0 | Z11: ='Fats Raw Data'!AS11-'Fats Raw Data'!BC11 -> 0 | AA11: ='Fats Raw Data'!AW11&" - "&'Fats Raw Data'!BG11 -> - | AC11: ='Fats Raw Data'!AY11 -> 0 | AD11: ='Fats Raw Data'!AZ11-'Fats Raw Data'!B11 -> 0 | AE11: ='Fats Raw Data'!BA11-'Fats Raw Data'!C11 -> 0 | AF11: ='Fats Raw Data'!BB11-'Fats Raw Data'!D11 -> 0 | AG11: ='Fats Raw Data'!BC11-'Fats Raw Data'!E11 -> 0 | AH11: ='Fats Raw Data'!BG11&" - "&'Fats Raw Data'!I11 -> - | AJ11: ='Fats Raw Data'!A11 -> 0 | AK11: ='Fats Raw Data'!B11-'Fats Raw Data'!L11 -> 0 | AL11: ='Fats Raw Data'!C11-'Fats Raw Data'!M11 -> 0 | AM11: ='Fats Raw Data'!D11-'Fats Raw Data'!N11 -> 0 | AN11: ='Fats Raw Data'!E11-'Fats Raw Data'!O11 -> 0 | AO11: ='Fats Raw Data'!I11&" - "&'Fats Raw Data'!S11 -> - | AQ11: ='Fats Raw Data'!AE11 -> 0 | AR11: ='Fats Raw Data'!AF11-'Fats Raw Data'!AZ11 -> 0 | AS11: ='Fats Raw Data'!AG11-'Fats Raw Data'!BA11 -> 0 | AT11: ='Fats Raw Data'!AH11-'Fats Raw Data'!BB11 -> 0 | AU11: ='Fats Raw Data'!AI11-'Fats Raw Data'!BC11 -> 0 | AV11: ='Fats Raw Data'!AM11&" - "&'Fats Raw Data'!BG11 -> - | AX11: ='Fats Raw Data'!A11 -> 0 | AY11: ='Fats Raw Data'!B11-'Fats Raw Data'!V11 -> 0 | AZ11: ='Fats Raw Data'!C11-'Fats Raw Data'!W11 -> 0 | BA11: ='Fats Raw Data'!D11-'Fats Raw Data'!X11 -> 0 | BB11: ='Fats Raw Data'!E11-'Fats Raw Data'!Y11 -> 0 | BC11: ='Fats Raw Data'!I11&" - "&'Fats Raw Data'!AC11 -> - | BE11: ='Fats Raw Data'!K11 -> 0 | BF11: ='Fats Raw Data'!L11-'Fats Raw Data'!AF11 -> 0 | BG11: ='Fats Raw Data'!M11-'Fats Raw Data'!AG11 -> 0 | BH11: ='Fats Raw Data'!N11-'Fats Raw Data'!AH11 -> 0 | BI11: ='Fats Raw Data'!O11-'Fats Raw Data'!AI11 -> 0 | BJ11: ='Fats Raw Data'!S11&" - "&'Fats Raw Data'!AM11 -> -
A12: ='Fats Raw Data'!K12 -> 0 | B12: ='Fats Raw Data'!L12-'Fats Raw Data'!V12 -> 0 | C12: ='Fats Raw Data'!M12-'Fats Raw Data'!W12 -> 0 | D12: ='Fats Raw Data'!N12-'Fats Raw Data'!X12 -> 0 | E12: ='Fats Raw Data'!O12-'Fats Raw Data'!Y12 -> 0 | F12: ='Fats Raw Data'!S12&" - "&'Fats Raw Data'!AC12 -> - | H12: ='Fats Raw Data'!U12 -> 0 | I12: ='Fats Raw Data'!V12-'Fats Raw Data'!AF12 -> 0 | J12: ='Fats Raw Data'!W12-'Fats Raw Data'!AG12 -> 0 | K12: ='Fats Raw Data'!X12-'Fats Raw Data'!AH12 -> 0 | L12: ='Fats Raw Data'!Y12-'Fats Raw Data'!AI12 -> 0 | M12: ='Fats Raw Data'!AC12&" - "&'Fats Raw Data'!AM12 -> - | O12: ='Fats Raw Data'!AE12 -> 0 | P12: ='Fats Raw Data'!AF12-'Fats Raw Data'!AP12 -> 0 | Q12: ='Fats Raw Data'!AG12-'Fats Raw Data'!AQ12 -> 0 | R12: ='Fats Raw Data'!AH12-'Fats Raw Data'!AR12 -> 0 | S12: ='Fats Raw Data'!AI12-'Fats Raw Data'!AS12 -> 0 | T12: ='Fats Raw Data'!AM12&" - "&'Fats Raw Data'!AW12 -> - | V12: ='Fats Raw Data'!AO12 -> 0 | W12: ='Fats Raw Data'!AP12-'Fats Raw Data'!AZ12 -> 0 | X12: ='Fats Raw Data'!AQ12-'Fats Raw Data'!BA12 -> 0 | Y12: ='Fats Raw Data'!AR12-'Fats Raw Data'!BB12 -> 0 | Z12: ='Fats Raw Data'!AS12-'Fats Raw Data'!BC12 -> 0 | AA12: ='Fats Raw Data'!AW12&" - "&'Fats Raw Data'!BG12 -> - | AC12: ='Fats Raw Data'!AY12 -> 0 | AD12: ='Fats Raw Data'!AZ12-'Fats Raw Data'!B12 -> 0 | AE12: ='Fats Raw Data'!BA12-'Fats Raw Data'!C12 -> 0 | AF12: ='Fats Raw Data'!BB12-'Fats Raw Data'!D12 -> 0 | AG12: ='Fats Raw Data'!BC12-'Fats Raw Data'!E12 -> 0 | AH12: ='Fats Raw Data'!BG12&" - "&'Fats Raw Data'!I12 -> - | AJ12: ='Fats Raw Data'!A12 -> 0 | AK12: ='Fats Raw Data'!B12-'Fats Raw Data'!L12 -> 0 | AL12: ='Fats Raw Data'!C12-'Fats Raw Data'!M12 -> 0 | AM12: ='Fats Raw Data'!D12-'Fats Raw Data'!N12 -> 0 | AN12: ='Fats Raw Data'!E12-'Fats Raw Data'!O12 -> 0 | AO12: ='Fats Raw Data'!I12&" - "&'Fats Raw Data'!S12 -> - | AQ12: ='Fats Raw Data'!AE12 -> 0 | AR12: ='Fats Raw Data'!AF12-'Fats Raw Data'!AZ12 -> 0 | AS12: ='Fats Raw Data'!AG12-'Fats Raw Data'!BA12 -> 0 | AT12: ='Fats Raw Data'!AH12-'Fats Raw Data'!BB12 -> 0 | AU12: ='Fats Raw Data'!AI12-'Fats Raw Data'!BC12 -> 0 | AV12: ='Fats Raw Data'!AM12&" - "&'Fats Raw Data'!BG12 -> - | AX12: ='Fats Raw Data'!A12 -> 0 | AY12: ='Fats Raw Data'!B12-'Fats Raw Data'!V12 -> 0 | AZ12: ='Fats Raw Data'!C12-'Fats Raw Data'!W12 -> 0 | BA12: ='Fats Raw Data'!D12-'Fats Raw Data'!X12 -> 0 | BB12: ='Fats Raw Data'!E12-'Fats Raw Data'!Y12 -> 0 | BC12: ='Fats Raw Data'!I12&" - "&'Fats Raw Data'!AC12 -> - | BE12: ='Fats Raw Data'!K12 -> 0 | BF12: ='Fats Raw Data'!L12-'Fats Raw Data'!AF12 -> 0 | BG12: ='Fats Raw Data'!M12-'Fats Raw Data'!AG12 -> 0 | BH12: ='Fats Raw Data'!N12-'Fats Raw Data'!AH12 -> 0 | BI12: ='Fats Raw Data'!O12-'Fats Raw Data'!AI12 -> 0 | BJ12: ='Fats Raw Data'!S12&" - "&'Fats Raw Data'!AM12 -> -
A13: ='Fats Raw Data'!K13 -> 0 | B13: ='Fats Raw Data'!L13-'Fats Raw Data'!V13 -> 0 | C13: ='Fats Raw Data'!M13-'Fats Raw Data'!W13 -> 0 | D13: ='Fats Raw Data'!N13-'Fats Raw Data'!X13 -> 0 | E13: ='Fats Raw Data'!O13-'Fats Raw Data'!Y13 -> 0 | F13: ='Fats Raw Data'!S13&" - "&'Fats Raw Data'!AC13 -> - | H13: ='Fats Raw Data'!U13 -> 0 | I13: ='Fats Raw Data'!V13-'Fats Raw Data'!AF13 -> 0 | J13: ='Fats Raw Data'!W13-'Fats Raw Data'!AG13 -> 0 | K13: ='Fats Raw Data'!X13-'Fats Raw Data'!AH13 -> 0 | L13: ='Fats Raw Data'!Y13-'Fats Raw Data'!AI13 -> 0 | M13: ='Fats Raw Data'!AC13&" - "&'Fats Raw Data'!AM13 -> - | O13: ='Fats Raw Data'!AE13 -> 0 | P13: ='Fats Raw Data'!AF13-'Fats Raw Data'!AP13 -> 0 | Q13: ='Fats Raw Data'!AG13-'Fats Raw Data'!AQ13 -> 0 | R13: ='Fats Raw Data'!AH13-'Fats Raw Data'!AR13 -> 0 | S13: ='Fats Raw Data'!AI13-'Fats Raw Data'!AS13 -> 0 | T13: ='Fats Raw Data'!AM13&" - "&'Fats Raw Data'!AW13 -> - | V13: ='Fats Raw Data'!AO13 -> 0 | W13: ='Fats Raw Data'!AP13-'Fats Raw Data'!AZ13 -> 0 | X13: ='Fats Raw Data'!AQ13-'Fats Raw Data'!BA13 -> 0 | Y13: ='Fats Raw Data'!AR13-'Fats Raw Data'!BB13 -> 0 | Z13: ='Fats Raw Data'!AS13-'Fats Raw Data'!BC13 -> 0 | AA13: ='Fats Raw Data'!AW13&" - "&'Fats Raw Data'!BG13 -> - | AC13: ='Fats Raw Data'!AY13 -> 0 | AD13: ='Fats Raw Data'!AZ13-'Fats Raw Data'!B13 -> 0 | AE13: ='Fats Raw Data'!BA13-'Fats Raw Data'!C13 -> 0 | AF13: ='Fats Raw Data'!BB13-'Fats Raw Data'!D13 -> 0 | AG13: ='Fats Raw Data'!BC13-'Fats Raw Data'!E13 -> 0 | AH13: ='Fats Raw Data'!BG13&" - "&'Fats Raw Data'!I13 -> - | AJ13: ='Fats Raw Data'!A13 -> 0 | AK13: ='Fats Raw Data'!B13-'Fats Raw Data'!L13 -> 0 | AL13: ='Fats Raw Data'!C13-'Fats Raw Data'!M13 -> 0 | AM13: ='Fats Raw Data'!D13-'Fats Raw Data'!N13 -> 0 | AN13: ='Fats Raw Data'!E13-'Fats Raw Data'!O13 -> 0 | AO13: ='Fats Raw Data'!I13&" - "&'Fats Raw Data'!S13 -> - | AQ13: ='Fats Raw Data'!AE13 -> 0 | AR13: ='Fats Raw Data'!AF13-'Fats Raw Data'!AZ13 -> 0 | AS13: ='Fats Raw Data'!AG13-'Fats Raw Data'!BA13 -> 0 | AT13: ='Fats Raw Data'!AH13-'Fats Raw Data'!BB13 -> 0 | AU13: ='Fats Raw Data'!AI13-'Fats Raw Data'!BC13 -> 0 | AV13: ='Fats Raw Data'!AM13&" - "&'Fats Raw Data'!BG13 -> - | AX13: ='Fats Raw Data'!A13 -> 0 | AY13: ='Fats Raw Data'!B13-'Fats Raw Data'!V13 -> 0 | AZ13: ='Fats Raw Data'!C13-'Fats Raw Data'!W13 -> 0 | BA13: ='Fats Raw Data'!D13-'Fats Raw Data'!X13 -> 0 | BB13: ='Fats Raw Data'!E13-'Fats Raw Data'!Y13 -> 0 | BC13: ='Fats Raw Data'!I13&" - "&'Fats Raw Data'!AC13 -> - | BE13: ='Fats Raw Data'!K13 -> 0 | BF13: ='Fats Raw Data'!L13-'Fats Raw Data'!AF13 -> 0 | BG13: ='Fats Raw Data'!M13-'Fats Raw Data'!AG13 -> 0 | BH13: ='Fats Raw Data'!N13-'Fats Raw Data'!AH13 -> 0 | BI13: ='Fats Raw Data'!O13-'Fats Raw Data'!AI13 -> 0 | BJ13: ='Fats Raw Data'!S13&" - "&'Fats Raw Data'!AM13 -> -
A14: ='Fats Raw Data'!K14 -> 0 | B14: ='Fats Raw Data'!L14-'Fats Raw Data'!V14 -> 0 | C14: ='Fats Raw Data'!M14-'Fats Raw Data'!W14 -> 0 | D14: ='Fats Raw Data'!N14-'Fats Raw Data'!X14 -> 0 | E14: ='Fats Raw Data'!O14-'Fats Raw Data'!Y14 -> 0 | F14: ='Fats Raw Data'!S14&" - "&'Fats Raw Data'!AC14 -> - | H14: ='Fats Raw Data'!U14 -> 0 | I14: ='Fats Raw Data'!V14-'Fats Raw Data'!AF14 -> 0 | J14: ='Fats Raw Data'!W14-'Fats Raw Data'!AG14 -> 0 | K14: ='Fats Raw Data'!X14-'Fats Raw Data'!AH14 -> 0 | L14: ='Fats Raw Data'!Y14-'Fats Raw Data'!AI14 -> 0 | M14: ='Fats Raw Data'!AC14&" - "&'Fats Raw Data'!AM14 -> - | O14: ='Fats Raw Data'!AE14 -> 0 | P14: ='Fats Raw Data'!AF14-'Fats Raw Data'!AP14 -> 0 | Q14: ='Fats Raw Data'!AG14-'Fats Raw Data'!AQ14 -> 0 | R14: ='Fats Raw Data'!AH14-'Fats Raw Data'!AR14 -> 0 | S14: ='Fats Raw Data'!AI14-'Fats Raw Data'!AS14 -> 0 | T14: ='Fats Raw Data'!AM14&" - "&'Fats Raw Data'!AW14 -> - | V14: ='Fats Raw Data'!AO14 -> 0 | W14: ='Fats Raw Data'!AP14-'Fats Raw Data'!AZ14 -> 0 | X14: ='Fats Raw Data'!AQ14-'Fats Raw Data'!BA14 -> 0 | Y14: ='Fats Raw Data'!AR14-'Fats Raw Data'!BB14 -> 0 | Z14: ='Fats Raw Data'!AS14-'Fats Raw Data'!BC14 -> 0 | AA14: ='Fats Raw Data'!AW14&" - "&'Fats Raw Data'!BG14 -> - | AC14: ='Fats Raw Data'!AY14 -> 0 | AD14: ='Fats Raw Data'!AZ14-'Fats Raw Data'!B14 -> 0 | AE14: ='Fats Raw Data'!BA14-'Fats Raw Data'!C14 -> 0 | AF14: ='Fats Raw Data'!BB14-'Fats Raw Data'!D14 -> 0 | AG14: ='Fats Raw Data'!BC14-'Fats Raw Data'!E14 -> 0 | AH14: ='Fats Raw Data'!BG14&" - "&'Fats Raw Data'!I14 -> - | AJ14: ='Fats Raw Data'!A14 -> 0 | AK14: ='Fats Raw Data'!B14-'Fats Raw Data'!L14 -> 0 | AL14: ='Fats Raw Data'!C14-'Fats Raw Data'!M14 -> 0 | AM14: ='Fats Raw Data'!D14-'Fats Raw Data'!N14 -> 0 | AN14: ='Fats Raw Data'!E14-'Fats Raw Data'!O14 -> 0 | AO14: ='Fats Raw Data'!I14&" - "&'Fats Raw Data'!S14 -> - | AQ14: ='Fats Raw Data'!AE14 -> 0 | AR14: ='Fats Raw Data'!AF14-'Fats Raw Data'!AZ14 -> 0 | AS14: ='Fats Raw Data'!AG14-'Fats Raw Data'!BA14 -> 0 | AT14: ='Fats Raw Data'!AH14-'Fats Raw Data'!BB14 -> 0 | AU14: ='Fats Raw Data'!AI14-'Fats Raw Data'!BC14 -> 0 | AV14: ='Fats Raw Data'!AM14&" - "&'Fats Raw Data'!BG14 -> - | AX14: ='Fats Raw Data'!A14 -> 0 | AY14: ='Fats Raw Data'!B14-'Fats Raw Data'!V14 -> 0 | AZ14: ='Fats Raw Data'!C14-'Fats Raw Data'!W14 -> 0 | BA14: ='Fats Raw Data'!D14-'Fats Raw Data'!X14 -> 0 | BB14: ='Fats Raw Data'!E14-'Fats Raw Data'!Y14 -> 0 | BC14: ='Fats Raw Data'!I14&" - "&'Fats Raw Data'!AC14 -> - | BE14: ='Fats Raw Data'!K14 -> 0 | BF14: ='Fats Raw Data'!L14-'Fats Raw Data'!AF14 -> 0 | BG14: ='Fats Raw Data'!M14-'Fats Raw Data'!AG14 -> 0 | BH14: ='Fats Raw Data'!N14-'Fats Raw Data'!AH14 -> 0 | BI14: ='Fats Raw Data'!O14-'Fats Raw Data'!AI14 -> 0 | BJ14: ='Fats Raw Data'!S14&" - "&'Fats Raw Data'!AM14 -> -
... A120: ='Fats Raw Data'!K120 -> 0 | B120: ='Fats Raw Data'!L120-'Fats Raw Data'!V120 -> 0 | C120: ='Fats Raw Data'!M120-'Fats Raw Data'!W120 -> 0 | D120: ='Fats Raw Data'!N120-'Fats Raw Data'!X120 -> 0 | E120: ='Fats Raw Data'!O120-'Fats Raw Data'!Y120 -> 0 | F120: ='Fats Raw Data'!S120&" - "&'Fats Raw Data'!AC120 -> - | H120: ='Fats Raw Data'!U120 -> 0 | I120: ='Fats Raw Data'!V120-'Fats Raw Data'!AF120 -> 0 | J120: ='Fats Raw Data'!W120-'Fats Raw Data'!AG120 -> 0 | K120: ='Fats Raw Data'!X120-'Fats Raw Data'!AH120 -> 0 | L120: ='Fats Raw Data'!Y120-'Fats Raw Data'!AI120 -> 0 | M120: ='Fats Raw Data'!AC120&" - "&'Fats Raw Data'!AM120 -> - | O120: ='Fats Raw Data'!AE120 -> 0 | P120: ='Fats Raw Data'!AF120-'Fats Raw Data'!AP120 -> 0 | Q120: ='Fats Raw Data'!AG120-'Fats Raw Data'!AQ120 -> 0 | R120: ='Fats Raw Data'!AH120-'Fats Raw Data'!AR120 -> 0 | S120: ='Fats Raw Data'!AI120-'Fats Raw Data'!AS120 -> 0 | T120: ='Fats Raw Data'!AM120&" - "&'Fats Raw Data'!AW120 -> - | V120: ='Fats Raw Data'!AO120 -> 0 | W120: ='Fats Raw Data'!AP120-'Fats Raw Data'!AZ120 -> 0 | X120: ='Fats Raw Data'!AQ120-'Fats Raw Data'!BA120 -> 0 | Y120: ='Fats Raw Data'!AR120-'Fats Raw Data'!BB120 -> 0 | Z120: ='Fats Raw Data'!AS120-'Fats Raw Data'!BC120 -> 0 | AA120: ='Fats Raw Data'!AW120&" - "&'Fats Raw Data'!BG120 -> - | AC120: ='Fats Raw Data'!AY120 -> 0 | AD120: ='Fats Raw Data'!AZ120-'Fats Raw Data'!B120 -> 0 | AE120: ='Fats Raw Data'!BA120-'Fats Raw Data'!C120 -> 0 | AF120: ='Fats Raw Data'!BB120-'Fats Raw Data'!D120 -> 0 | AG120: ='Fats Raw Data'!BC120-'Fats Raw Data'!E120 -> 0 | AH120: ='Fats Raw Data'!BG120&" - "&'Fats Raw Data'!I120 -> - | AJ120: ='Fats Raw Data'!A120 -> 0 | AK120: ='Fats Raw Data'!B120-'Fats Raw Data'!L120 -> 0 | AL120: ='Fats Raw Data'!C120-'Fats Raw Data'!M120 -> 0 | AM120: ='Fats Raw Data'!D120-'Fats Raw Data'!N120 -> 0 | AN120: ='Fats Raw Data'!E120-'Fats Raw Data'!O120 -> 0 | AO120: ='Fats Raw Data'!I120&" - "&'Fats Raw Data'!S120 -> - | AQ120: ='Fats Raw Data'!AE120 -> 0 | AR120: ='Fats Raw Data'!AF120-'Fats Raw Data'!AZ120 -> 0 | AS120: ='Fats Raw Data'!AG120-'Fats Raw Data'!BA120 -> 0 | AT120: ='Fats Raw Data'!AH120-'Fats Raw Data'!BB120 -> 0 | AU120: ='Fats Raw Data'!AI120-'Fats Raw Data'!BC120 -> 0 | AV120: ='Fats Raw Data'!AM120&" - "&'Fats Raw Data'!BG120 -> - | AX120: ='Fats Raw Data'!A120 -> 0 | AY120: ='Fats Raw Data'!B120-'Fats Raw Data'!V120 -> 0 | AZ120: ='Fats Raw Data'!C120-'Fats Raw Data'!W120 -> 0 | BA120: ='Fats Raw Data'!D120-'Fats Raw Data'!X120 -> 0 | BB120: ='Fats Raw Data'!E120-'Fats Raw Data'!Y120 -> 0 | BC120: ='Fats Raw Data'!I120&" - "&'Fats Raw Data'!AC120 -> - | BE120: ='Fats Raw Data'!K120 -> 0 | BF120: ='Fats Raw Data'!L120-'Fats Raw Data'!AF120 -> 0 | BG120: ='Fats Raw Data'!M120-'Fats Raw Data'!AG120 -> 0 | BH120: ='Fats Raw Data'!N120-'Fats Raw Data'!AH120 -> 0 | BI120: ='Fats Raw Data'!O120-'Fats Raw Data'!AI120 -> 0 | BJ120: ='Fats Raw Data'!S120&" - "&'Fats Raw Data'!AM120 -> -

Sheet Feeder Spreads
A1: GFF - GFH (16 Years) | H1: GFK - GFQ (16 Years) | O1: GFV - GFX (16 Years) | V1: GFH - GFJ (16 Years) | AC1: GFJ - GFK (16 Years) | AJ1: GFQ - GFU (16 Years) | AQ1: GFU - GFV (16 Years) | AX1: GFX - GFF (16 Years)
A2: Date | B2: Close | C2: Open | D2: High | E2: Low | F2: Spread Year | H2: Date | I2: Close | J2: Open | K2: High | L2: Low | M2: Spread Year | O2: Date | P2: Close | Q2: Open | R2: High | S2: Low | T2: Spread Year | V2: Date | W2: Close | X2: Open | Y2: High | Z2: Low | AA2: Spread Year | AC2: Date | AD2: Close | AE2: Open | AF2: High | AG2: Low | AH2: Spread Year | AJ2: Date | AK2: Close | AL2: Open | AM2: High | AN2: Low | AO2: Spread Year | AQ2: Date | AR2: Close | AS2: Open | AT2: High | AU2: Low | AV2: Spread Year | AX2: Date | AY2: Close | AZ2: Open | BA2: High | BB2: Low | BC2: Spread Year
A3: ='Feeders Raw Data'!A3 -> 46150 | B3: ='Feeders Raw Data'!B3-'Feeders Raw Data'!L3 -> 4.45 | C3: ='Feeders Raw Data'!C3-'Feeders Raw Data'!M3 -> 7.75 | D3: ='Feeders Raw Data'!D3-'Feeders Raw Data'!N3 -> 5.675 | E3: ='Feeders Raw Data'!E3-'Feeders Raw Data'!O3 -> 4.375 | F3: ='Feeders Raw Data'!I3&" - "&'Feeders Raw Data'!S3 -> GFF27 - GFH27 | H3: ='Feeders Raw Data'!AE3 -> 46150 | I3: ='Feeders Raw Data'!AF3-'Feeders Raw Data'!AP3 -> 3.15 | J3: ='Feeders Raw Data'!AG3-'Feeders Raw Data'!AQ3 -> -0.175 | K3: ='Feeders Raw Data'!AH3-'Feeders Raw Data'!AR3 -> -0.15 | L3: ='Feeders Raw Data'!AI3-'Feeders Raw Data'!AS3 -> 3.425 | M3: ='Feeders Raw Data'!AM3&" - "&'Feeders Raw Data'!AW3 -> GFK26 - GFQ26 | O3: ='Feeders Raw Data'!BI3 -> 46150 | P3: ='Feeders Raw Data'!BJ3-'Feeders Raw Data'!BT3 -> 3.075 | Q3: ='Feeders Raw Data'!BK3-'Feeders Raw Data'!BU3 -> 4.05 | R3: ='Feeders Raw Data'!BL3-'Feeders Raw Data'!BV3 -> 2.775 | S3: ='Feeders Raw Data'!BM3-'Feeders Raw Data'!BW3 -> 2.85 | T3: ='Feeders Raw Data'!BQ3&" - "&'Feeders Raw Data'!CA3 -> GFV26 - GFX26 | V3: ='Feeders Raw Data'!K3 -> 46150 | W3: ='Feeders Raw Data'!L3-'Feeders Raw Data'!V3 -> 1.675 | X3: ='Feeders Raw Data'!M3-'Feeders Raw Data'!W3 -> 5.95 | Y3: ='Feeders Raw Data'!N3-'Feeders Raw Data'!X3 -> 2.225 | Z3: ='Feeders Raw Data'!O3-'Feeders Raw Data'!Y3 -> 1.825 | AA3: ='Feeders Raw Data'!S3&" - "&'Feeders Raw Data'!AC3 -> GFH27 - GFJ27 | AC3: ='Feeders Raw Data'!U3 -> 46150 | AD3: ='Feeders Raw Data'!V3-'Feeders Raw Data'!AF3 -> -22.85 | AE3: ='Feeders Raw Data'!W3-'Feeders Raw Data'!AG3 -> -24.925 | AF3: ='Feeders Raw Data'!X3-'Feeders Raw Data'!AH3 -> -20.45 | AG3: ='Feeders Raw Data'!Y3-'Feeders Raw Data'!AI3 -> -22.375 | AH3: ='Feeders Raw Data'!AC3&" - "&'Feeders Raw Data'!AM3 -> GFJ27 - GFK26 | AJ3: ='Feeders Raw Data'!AO3 -> 46150 | AK3: ='Feeders Raw Data'!AP3-'Feeders Raw Data'!AZ3 -> 2 | AL3: ='Feeders Raw Data'!AQ3-'Feeders Raw Data'!BA3 -> 1.275 | AM3: ='Feeders Raw Data'!AR3-'Feeders Raw Data'!BB3 -> 1.4 | AN3: ='Feeders Raw Data'!AS3-'Feeders Raw Data'!BC3 -> 1.75 | AO3: ='Feeders Raw Data'!AW3&" - "&'Feeders Raw Data'!BG3 -> GFQ26 - GFU26 | AQ3: ='Feeders Raw Data'!AY3 -> 46150 | AR3: ='Feeders Raw Data'!AZ3-'Feeders Raw Data'!BJ3 -> 2.425 | AS3: ='Feeders Raw Data'!BA3-'Feeders Raw Data'!BK3 -> 1.7 | AT3: ='Feeders Raw Data'!BB3-'Feeders Raw Data'!BL3 -> 2.525 | AU3: ='Feeders Raw Data'!BC3-'Feeders Raw Data'!BM3 -> 2.25 | AV3: ='Feeders Raw Data'!BG3&" - "&'Feeders Raw Data'!BQ3 -> GFU26 - GFV26 | AX3: ='Feeders Raw Data'!BS3 -> 46150 | AY3: ='Feeders Raw Data'!BT3-'Feeders Raw Data'!B3 -> 6.075 | AZ3: ='Feeders Raw Data'!BU3-'Feeders Raw Data'!C3 -> 4.375 | BA3: ='Feeders Raw Data'!BV3-'Feeders Raw Data'!D3 -> 6 | BB3: ='Feeders Raw Data'!BW3-'Feeders Raw Data'!E3 -> 5.9 | BC3: ='Feeders Raw Data'!CA3&" - "&'Feeders Raw Data'!I3 -> GFX26 - GFF27
A4: ='Feeders Raw Data'!A4 -> 0 | B4: ='Feeders Raw Data'!B4-'Feeders Raw Data'!L4 -> 0 | C4: ='Feeders Raw Data'!C4-'Feeders Raw Data'!M4 -> 0 | D4: ='Feeders Raw Data'!D4-'Feeders Raw Data'!N4 -> 0 | E4: ='Feeders Raw Data'!E4-'Feeders Raw Data'!O4 -> 0 | F4: ='Feeders Raw Data'!I4&" - "&'Feeders Raw Data'!S4 -> - | H4: ='Feeders Raw Data'!AE4 -> 0 | I4: ='Feeders Raw Data'!AF4-'Feeders Raw Data'!AP4 -> 0 | J4: ='Feeders Raw Data'!AG4-'Feeders Raw Data'!AQ4 -> 0 | K4: ='Feeders Raw Data'!AH4-'Feeders Raw Data'!AR4 -> 0 | L4: ='Feeders Raw Data'!AI4-'Feeders Raw Data'!AS4 -> 0 | M4: ='Feeders Raw Data'!AM4&" - "&'Feeders Raw Data'!AW4 -> - | O4: ='Feeders Raw Data'!BI4 -> 0 | P4: ='Feeders Raw Data'!BJ4-'Feeders Raw Data'!BT4 -> 0 | Q4: ='Feeders Raw Data'!BK4-'Feeders Raw Data'!BU4 -> 0 | R4: ='Feeders Raw Data'!BL4-'Feeders Raw Data'!BV4 -> 0 | S4: ='Feeders Raw Data'!BM4-'Feeders Raw Data'!BW4 -> 0 | T4: ='Feeders Raw Data'!BQ4&" - "&'Feeders Raw Data'!CA4 -> - | V4: ='Feeders Raw Data'!K4 -> 0 | W4: ='Feeders Raw Data'!L4-'Feeders Raw Data'!V4 -> 0 | X4: ='Feeders Raw Data'!M4-'Feeders Raw Data'!W4 -> 0 | Y4: ='Feeders Raw Data'!N4-'Feeders Raw Data'!X4 -> 0 | Z4: ='Feeders Raw Data'!O4-'Feeders Raw Data'!Y4 -> 0 | AA4: ='Feeders Raw Data'!S4&" - "&'Feeders Raw Data'!AC4 -> - | AC4: ='Feeders Raw Data'!U4 -> 0 | AD4: ='Feeders Raw Data'!V4-'Feeders Raw Data'!AF4 -> 0 | AE4: ='Feeders Raw Data'!W4-'Feeders Raw Data'!AG4 -> 0 | AF4: ='Feeders Raw Data'!X4-'Feeders Raw Data'!AH4 -> 0 | AG4: ='Feeders Raw Data'!Y4-'Feeders Raw Data'!AI4 -> 0 | AH4: ='Feeders Raw Data'!AC4&" - "&'Feeders Raw Data'!AM4 -> - | AJ4: ='Feeders Raw Data'!AO4 -> 0 | AK4: ='Feeders Raw Data'!AP4-'Feeders Raw Data'!AZ4 -> 0 | AL4: ='Feeders Raw Data'!AQ4-'Feeders Raw Data'!BA4 -> 0 | AM4: ='Feeders Raw Data'!AR4-'Feeders Raw Data'!BB4 -> 0 | AN4: ='Feeders Raw Data'!AS4-'Feeders Raw Data'!BC4 -> 0 | AO4: ='Feeders Raw Data'!AW4&" - "&'Feeders Raw Data'!BG4 -> - | AQ4: ='Feeders Raw Data'!AY4 -> 0 | AR4: ='Feeders Raw Data'!AZ4-'Feeders Raw Data'!BJ4 -> 0 | AS4: ='Feeders Raw Data'!BA4-'Feeders Raw Data'!BK4 -> 0 | AT4: ='Feeders Raw Data'!BB4-'Feeders Raw Data'!BL4 -> 0 | AU4: ='Feeders Raw Data'!BC4-'Feeders Raw Data'!BM4 -> 0 | AV4: ='Feeders Raw Data'!BG4&" - "&'Feeders Raw Data'!BQ4 -> - | AX4: ='Feeders Raw Data'!BS4 -> 0 | AY4: ='Feeders Raw Data'!BT4-'Feeders Raw Data'!B4 -> 0 | AZ4: ='Feeders Raw Data'!BU4-'Feeders Raw Data'!C4 -> 0 | BA4: ='Feeders Raw Data'!BV4-'Feeders Raw Data'!D4 -> 0 | BB4: ='Feeders Raw Data'!BW4-'Feeders Raw Data'!E4 -> 0 | BC4: ='Feeders Raw Data'!CA4&" - "&'Feeders Raw Data'!I4 -> -
A5: ='Feeders Raw Data'!A5 -> 0 | B5: ='Feeders Raw Data'!B5-'Feeders Raw Data'!L5 -> 0 | C5: ='Feeders Raw Data'!C5-'Feeders Raw Data'!M5 -> 0 | D5: ='Feeders Raw Data'!D5-'Feeders Raw Data'!N5 -> 0 | E5: ='Feeders Raw Data'!E5-'Feeders Raw Data'!O5 -> 0 | F5: ='Feeders Raw Data'!I5&" - "&'Feeders Raw Data'!S5 -> - | H5: ='Feeders Raw Data'!AE5 -> 0 | I5: ='Feeders Raw Data'!AF5-'Feeders Raw Data'!AP5 -> 0 | J5: ='Feeders Raw Data'!AG5-'Feeders Raw Data'!AQ5 -> 0 | K5: ='Feeders Raw Data'!AH5-'Feeders Raw Data'!AR5 -> 0 | L5: ='Feeders Raw Data'!AI5-'Feeders Raw Data'!AS5 -> 0 | M5: ='Feeders Raw Data'!AM5&" - "&'Feeders Raw Data'!AW5 -> - | O5: ='Feeders Raw Data'!BI5 -> 0 | P5: ='Feeders Raw Data'!BJ5-'Feeders Raw Data'!BT5 -> 0 | Q5: ='Feeders Raw Data'!BK5-'Feeders Raw Data'!BU5 -> 0 | R5: ='Feeders Raw Data'!BL5-'Feeders Raw Data'!BV5 -> 0 | S5: ='Feeders Raw Data'!BM5-'Feeders Raw Data'!BW5 -> 0 | T5: ='Feeders Raw Data'!BQ5&" - "&'Feeders Raw Data'!CA5 -> - | V5: ='Feeders Raw Data'!K5 -> 0 | W5: ='Feeders Raw Data'!L5-'Feeders Raw Data'!V5 -> 0 | X5: ='Feeders Raw Data'!M5-'Feeders Raw Data'!W5 -> 0 | Y5: ='Feeders Raw Data'!N5-'Feeders Raw Data'!X5 -> 0 | Z5: ='Feeders Raw Data'!O5-'Feeders Raw Data'!Y5 -> 0 | AA5: ='Feeders Raw Data'!S5&" - "&'Feeders Raw Data'!AC5 -> - | AC5: ='Feeders Raw Data'!U5 -> 0 | AD5: ='Feeders Raw Data'!V5-'Feeders Raw Data'!AF5 -> 0 | AE5: ='Feeders Raw Data'!W5-'Feeders Raw Data'!AG5 -> 0 | AF5: ='Feeders Raw Data'!X5-'Feeders Raw Data'!AH5 -> 0 | AG5: ='Feeders Raw Data'!Y5-'Feeders Raw Data'!AI5 -> 0 | AH5: ='Feeders Raw Data'!AC5&" - "&'Feeders Raw Data'!AM5 -> - | AJ5: ='Feeders Raw Data'!AO5 -> 0 | AK5: ='Feeders Raw Data'!AP5-'Feeders Raw Data'!AZ5 -> 0 | AL5: ='Feeders Raw Data'!AQ5-'Feeders Raw Data'!BA5 -> 0 | AM5: ='Feeders Raw Data'!AR5-'Feeders Raw Data'!BB5 -> 0 | AN5: ='Feeders Raw Data'!AS5-'Feeders Raw Data'!BC5 -> 0 | AO5: ='Feeders Raw Data'!AW5&" - "&'Feeders Raw Data'!BG5 -> - | AQ5: ='Feeders Raw Data'!AY5 -> 0 | AR5: ='Feeders Raw Data'!AZ5-'Feeders Raw Data'!BJ5 -> 0 | AS5: ='Feeders Raw Data'!BA5-'Feeders Raw Data'!BK5 -> 0 | AT5: ='Feeders Raw Data'!BB5-'Feeders Raw Data'!BL5 -> 0 | AU5: ='Feeders Raw Data'!BC5-'Feeders Raw Data'!BM5 -> 0 | AV5: ='Feeders Raw Data'!BG5&" - "&'Feeders Raw Data'!BQ5 -> - | AX5: ='Feeders Raw Data'!BS5 -> 0 | AY5: ='Feeders Raw Data'!BT5-'Feeders Raw Data'!B5 -> 0 | AZ5: ='Feeders Raw Data'!BU5-'Feeders Raw Data'!C5 -> 0 | BA5: ='Feeders Raw Data'!BV5-'Feeders Raw Data'!D5 -> 0 | BB5: ='Feeders Raw Data'!BW5-'Feeders Raw Data'!E5 -> 0 | BC5: ='Feeders Raw Data'!CA5&" - "&'Feeders Raw Data'!I5 -> -
A6: ='Feeders Raw Data'!A6 -> 0 | B6: ='Feeders Raw Data'!B6-'Feeders Raw Data'!L6 -> 0 | C6: ='Feeders Raw Data'!C6-'Feeders Raw Data'!M6 -> 0 | D6: ='Feeders Raw Data'!D6-'Feeders Raw Data'!N6 -> 0 | E6: ='Feeders Raw Data'!E6-'Feeders Raw Data'!O6 -> 0 | F6: ='Feeders Raw Data'!I6&" - "&'Feeders Raw Data'!S6 -> - | H6: ='Feeders Raw Data'!AE6 -> 0 | I6: ='Feeders Raw Data'!AF6-'Feeders Raw Data'!AP6 -> 0 | J6: ='Feeders Raw Data'!AG6-'Feeders Raw Data'!AQ6 -> 0 | K6: ='Feeders Raw Data'!AH6-'Feeders Raw Data'!AR6 -> 0 | L6: ='Feeders Raw Data'!AI6-'Feeders Raw Data'!AS6 -> 0 | M6: ='Feeders Raw Data'!AM6&" - "&'Feeders Raw Data'!AW6 -> - | O6: ='Feeders Raw Data'!BI6 -> 0 | P6: ='Feeders Raw Data'!BJ6-'Feeders Raw Data'!BT6 -> 0 | Q6: ='Feeders Raw Data'!BK6-'Feeders Raw Data'!BU6 -> 0 | R6: ='Feeders Raw Data'!BL6-'Feeders Raw Data'!BV6 -> 0 | S6: ='Feeders Raw Data'!BM6-'Feeders Raw Data'!BW6 -> 0 | T6: ='Feeders Raw Data'!BQ6&" - "&'Feeders Raw Data'!CA6 -> - | V6: ='Feeders Raw Data'!K6 -> 0 | W6: ='Feeders Raw Data'!L6-'Feeders Raw Data'!V6 -> 0 | X6: ='Feeders Raw Data'!M6-'Feeders Raw Data'!W6 -> 0 | Y6: ='Feeders Raw Data'!N6-'Feeders Raw Data'!X6 -> 0 | Z6: ='Feeders Raw Data'!O6-'Feeders Raw Data'!Y6 -> 0 | AA6: ='Feeders Raw Data'!S6&" - "&'Feeders Raw Data'!AC6 -> - | AC6: ='Feeders Raw Data'!U6 -> 0 | AD6: ='Feeders Raw Data'!V6-'Feeders Raw Data'!AF6 -> 0 | AE6: ='Feeders Raw Data'!W6-'Feeders Raw Data'!AG6 -> 0 | AF6: ='Feeders Raw Data'!X6-'Feeders Raw Data'!AH6 -> 0 | AG6: ='Feeders Raw Data'!Y6-'Feeders Raw Data'!AI6 -> 0 | AH6: ='Feeders Raw Data'!AC6&" - "&'Feeders Raw Data'!AM6 -> - | AJ6: ='Feeders Raw Data'!AO6 -> 0 | AK6: ='Feeders Raw Data'!AP6-'Feeders Raw Data'!AZ6 -> 0 | AL6: ='Feeders Raw Data'!AQ6-'Feeders Raw Data'!BA6 -> 0 | AM6: ='Feeders Raw Data'!AR6-'Feeders Raw Data'!BB6 -> 0 | AN6: ='Feeders Raw Data'!AS6-'Feeders Raw Data'!BC6 -> 0 | AO6: ='Feeders Raw Data'!AW6&" - "&'Feeders Raw Data'!BG6 -> - | AQ6: ='Feeders Raw Data'!AY6 -> 0 | AR6: ='Feeders Raw Data'!AZ6-'Feeders Raw Data'!BJ6 -> 0 | AS6: ='Feeders Raw Data'!BA6-'Feeders Raw Data'!BK6 -> 0 | AT6: ='Feeders Raw Data'!BB6-'Feeders Raw Data'!BL6 -> 0 | AU6: ='Feeders Raw Data'!BC6-'Feeders Raw Data'!BM6 -> 0 | AV6: ='Feeders Raw Data'!BG6&" - "&'Feeders Raw Data'!BQ6 -> - | AX6: ='Feeders Raw Data'!BS6 -> 0 | AY6: ='Feeders Raw Data'!BT6-'Feeders Raw Data'!B6 -> 0 | AZ6: ='Feeders Raw Data'!BU6-'Feeders Raw Data'!C6 -> 0 | BA6: ='Feeders Raw Data'!BV6-'Feeders Raw Data'!D6 -> 0 | BB6: ='Feeders Raw Data'!BW6-'Feeders Raw Data'!E6 -> 0 | BC6: ='Feeders Raw Data'!CA6&" - "&'Feeders Raw Data'!I6 -> -
A7: ='Feeders Raw Data'!A7 -> 0 | B7: ='Feeders Raw Data'!B7-'Feeders Raw Data'!L7 -> 0 | C7: ='Feeders Raw Data'!C7-'Feeders Raw Data'!M7 -> 0 | D7: ='Feeders Raw Data'!D7-'Feeders Raw Data'!N7 -> 0 | E7: ='Feeders Raw Data'!E7-'Feeders Raw Data'!O7 -> 0 | F7: ='Feeders Raw Data'!I7&" - "&'Feeders Raw Data'!S7 -> - | H7: ='Feeders Raw Data'!AE7 -> 0 | I7: ='Feeders Raw Data'!AF7-'Feeders Raw Data'!AP7 -> 0 | J7: ='Feeders Raw Data'!AG7-'Feeders Raw Data'!AQ7 -> 0 | K7: ='Feeders Raw Data'!AH7-'Feeders Raw Data'!AR7 -> 0 | L7: ='Feeders Raw Data'!AI7-'Feeders Raw Data'!AS7 -> 0 | M7: ='Feeders Raw Data'!AM7&" - "&'Feeders Raw Data'!AW7 -> - | O7: ='Feeders Raw Data'!BI7 -> 0 | P7: ='Feeders Raw Data'!BJ7-'Feeders Raw Data'!BT7 -> 0 | Q7: ='Feeders Raw Data'!BK7-'Feeders Raw Data'!BU7 -> 0 | R7: ='Feeders Raw Data'!BL7-'Feeders Raw Data'!BV7 -> 0 | S7: ='Feeders Raw Data'!BM7-'Feeders Raw Data'!BW7 -> 0 | T7: ='Feeders Raw Data'!BQ7&" - "&'Feeders Raw Data'!CA7 -> - | V7: ='Feeders Raw Data'!K7 -> 0 | W7: ='Feeders Raw Data'!L7-'Feeders Raw Data'!V7 -> 0 | X7: ='Feeders Raw Data'!M7-'Feeders Raw Data'!W7 -> 0 | Y7: ='Feeders Raw Data'!N7-'Feeders Raw Data'!X7 -> 0 | Z7: ='Feeders Raw Data'!O7-'Feeders Raw Data'!Y7 -> 0 | AA7: ='Feeders Raw Data'!S7&" - "&'Feeders Raw Data'!AC7 -> - | AC7: ='Feeders Raw Data'!U7 -> 0 | AD7: ='Feeders Raw Data'!V7-'Feeders Raw Data'!AF7 -> 0 | AE7: ='Feeders Raw Data'!W7-'Feeders Raw Data'!AG7 -> 0 | AF7: ='Feeders Raw Data'!X7-'Feeders Raw Data'!AH7 -> 0 | AG7: ='Feeders Raw Data'!Y7-'Feeders Raw Data'!AI7 -> 0 | AH7: ='Feeders Raw Data'!AC7&" - "&'Feeders Raw Data'!AM7 -> - | AJ7: ='Feeders Raw Data'!AO7 -> 0 | AK7: ='Feeders Raw Data'!AP7-'Feeders Raw Data'!AZ7 -> 0 | AL7: ='Feeders Raw Data'!AQ7-'Feeders Raw Data'!BA7 -> 0 | AM7: ='Feeders Raw Data'!AR7-'Feeders Raw Data'!BB7 -> 0 | AN7: ='Feeders Raw Data'!AS7-'Feeders Raw Data'!BC7 -> 0 | AO7: ='Feeders Raw Data'!AW7&" - "&'Feeders Raw Data'!BG7 -> - | AQ7: ='Feeders Raw Data'!AY7 -> 0 | AR7: ='Feeders Raw Data'!AZ7-'Feeders Raw Data'!BJ7 -> 0 | AS7: ='Feeders Raw Data'!BA7-'Feeders Raw Data'!BK7 -> 0 | AT7: ='Feeders Raw Data'!BB7-'Feeders Raw Data'!BL7 -> 0 | AU7: ='Feeders Raw Data'!BC7-'Feeders Raw Data'!BM7 -> 0 | AV7: ='Feeders Raw Data'!BG7&" - "&'Feeders Raw Data'!BQ7 -> - | AX7: ='Feeders Raw Data'!BS7 -> 0 | AY7: ='Feeders Raw Data'!BT7-'Feeders Raw Data'!B7 -> 0 | AZ7: ='Feeders Raw Data'!BU7-'Feeders Raw Data'!C7 -> 0 | BA7: ='Feeders Raw Data'!BV7-'Feeders Raw Data'!D7 -> 0 | BB7: ='Feeders Raw Data'!BW7-'Feeders Raw Data'!E7 -> 0 | BC7: ='Feeders Raw Data'!CA7&" - "&'Feeders Raw Data'!I7 -> -
A8: ='Feeders Raw Data'!A8 -> 0 | B8: ='Feeders Raw Data'!B8-'Feeders Raw Data'!L8 -> 0 | C8: ='Feeders Raw Data'!C8-'Feeders Raw Data'!M8 -> 0 | D8: ='Feeders Raw Data'!D8-'Feeders Raw Data'!N8 -> 0 | E8: ='Feeders Raw Data'!E8-'Feeders Raw Data'!O8 -> 0 | F8: ='Feeders Raw Data'!I8&" - "&'Feeders Raw Data'!S8 -> - | H8: ='Feeders Raw Data'!AE8 -> 0 | I8: ='Feeders Raw Data'!AF8-'Feeders Raw Data'!AP8 -> 0 | J8: ='Feeders Raw Data'!AG8-'Feeders Raw Data'!AQ8 -> 0 | K8: ='Feeders Raw Data'!AH8-'Feeders Raw Data'!AR8 -> 0 | L8: ='Feeders Raw Data'!AI8-'Feeders Raw Data'!AS8 -> 0 | M8: ='Feeders Raw Data'!AM8&" - "&'Feeders Raw Data'!AW8 -> - | O8: ='Feeders Raw Data'!BI8 -> 0 | P8: ='Feeders Raw Data'!BJ8-'Feeders Raw Data'!BT8 -> 0 | Q8: ='Feeders Raw Data'!BK8-'Feeders Raw Data'!BU8 -> 0 | R8: ='Feeders Raw Data'!BL8-'Feeders Raw Data'!BV8 -> 0 | S8: ='Feeders Raw Data'!BM8-'Feeders Raw Data'!BW8 -> 0 | T8: ='Feeders Raw Data'!BQ8&" - "&'Feeders Raw Data'!CA8 -> - | V8: ='Feeders Raw Data'!K8 -> 0 | W8: ='Feeders Raw Data'!L8-'Feeders Raw Data'!V8 -> 0 | X8: ='Feeders Raw Data'!M8-'Feeders Raw Data'!W8 -> 0 | Y8: ='Feeders Raw Data'!N8-'Feeders Raw Data'!X8 -> 0 | Z8: ='Feeders Raw Data'!O8-'Feeders Raw Data'!Y8 -> 0 | AA8: ='Feeders Raw Data'!S8&" - "&'Feeders Raw Data'!AC8 -> - | AC8: ='Feeders Raw Data'!U8 -> 0 | AD8: ='Feeders Raw Data'!V8-'Feeders Raw Data'!AF8 -> 0 | AE8: ='Feeders Raw Data'!W8-'Feeders Raw Data'!AG8 -> 0 | AF8: ='Feeders Raw Data'!X8-'Feeders Raw Data'!AH8 -> 0 | AG8: ='Feeders Raw Data'!Y8-'Feeders Raw Data'!AI8 -> 0 | AH8: ='Feeders Raw Data'!AC8&" - "&'Feeders Raw Data'!AM8 -> - | AJ8: ='Feeders Raw Data'!AO8 -> 0 | AK8: ='Feeders Raw Data'!AP8-'Feeders Raw Data'!AZ8 -> 0 | AL8: ='Feeders Raw Data'!AQ8-'Feeders Raw Data'!BA8 -> 0 | AM8: ='Feeders Raw Data'!AR8-'Feeders Raw Data'!BB8 -> 0 | AN8: ='Feeders Raw Data'!AS8-'Feeders Raw Data'!BC8 -> 0 | AO8: ='Feeders Raw Data'!AW8&" - "&'Feeders Raw Data'!BG8 -> - | AQ8: ='Feeders Raw Data'!AY8 -> 0 | AR8: ='Feeders Raw Data'!AZ8-'Feeders Raw Data'!BJ8 -> 0 | AS8: ='Feeders Raw Data'!BA8-'Feeders Raw Data'!BK8 -> 0 | AT8: ='Feeders Raw Data'!BB8-'Feeders Raw Data'!BL8 -> 0 | AU8: ='Feeders Raw Data'!BC8-'Feeders Raw Data'!BM8 -> 0 | AV8: ='Feeders Raw Data'!BG8&" - "&'Feeders Raw Data'!BQ8 -> - | AX8: ='Feeders Raw Data'!BS8 -> 0 | AY8: ='Feeders Raw Data'!BT8-'Feeders Raw Data'!B8 -> 0 | AZ8: ='Feeders Raw Data'!BU8-'Feeders Raw Data'!C8 -> 0 | BA8: ='Feeders Raw Data'!BV8-'Feeders Raw Data'!D8 -> 0 | BB8: ='Feeders Raw Data'!BW8-'Feeders Raw Data'!E8 -> 0 | BC8: ='Feeders Raw Data'!CA8&" - "&'Feeders Raw Data'!I8 -> -
